2023-05-18 23:32:11,456 - ERROR - An exception occurred: Can only use .str accessor with string values!
Traceback (most recent call last):
  File "C:\Users\alejo\AppData\Local\Temp\ipykernel_8984\3283861045.py", line 6, in <module>
    df['DISTANCE'] = df['DISTANCE'].str.replace(' miles', '')
  File "C:\Users\alejo\AppData\Local\Packages\PythonSoftwareFoundation.Python.3.10_qbz5n2kfra8p0\LocalCache\local-packages\Python310\site-packages\pandas\core\generic.py", line 5902, in __getattr__
    return object.__getattribute__(self, name)
  File "C:\Users\alejo\AppData\Local\Packages\PythonSoftwareFoundation.Python.3.10_qbz5n2kfra8p0\LocalCache\local-packages\Python310\site-packages\pandas\core\accessor.py", line 182, in __get__
    accessor_obj = self._accessor(obj)
  File "C:\Users\alejo\AppData\Local\Packages\PythonSoftwareFoundation.Python.3.10_qbz5n2kfra8p0\LocalCache\local-packages\Python310\site-packages\pandas\core\strings\accessor.py", line 181, in __init__
    self._inferred_dtype = self._validate(data)
  File "C:\Users\alejo\AppData\Local\Packages\PythonSoftwareFoundation.Python.3.10_qbz5n2kfra8p0\LocalCache\local-packages\Python310\site-packages\pandas\core\strings\accessor.py", line 235, in _validate
    raise AttributeError("Can only use .str accessor with string values!")
AttributeError: Can only use .str accessor with string values!
2023-05-18 23:40:50,808 - ERROR - Se ha presentado una excepcion: StringMethods.replace() missing 1 required positional argument: 'repl'
Traceback (most recent call last):
  File "C:\Users\alejo\AppData\Local\Temp\ipykernel_8984\4249438086.py", line 14, in <module>
    df['CANCELLED']=df['CANCELLED'].str.replace(valores_bool,regex=True)
  File "C:\Users\alejo\AppData\Local\Packages\PythonSoftwareFoundation.Python.3.10_qbz5n2kfra8p0\LocalCache\local-packages\Python310\site-packages\pandas\core\strings\accessor.py", line 129, in wrapper
    return func(self, *args, **kwargs)
TypeError: StringMethods.replace() missing 1 required positional argument: 'repl'
2023-05-18 23:40:50,808 - ERROR - Se ha presentado una excepcion: StringMethods.replace() missing 1 required positional argument: 'repl'
Traceback (most recent call last):
  File "C:\Users\alejo\AppData\Local\Temp\ipykernel_8984\4249438086.py", line 14, in <module>
    df['CANCELLED']=df['CANCELLED'].str.replace(valores_bool,regex=True)
  File "C:\Users\alejo\AppData\Local\Packages\PythonSoftwareFoundation.Python.3.10_qbz5n2kfra8p0\LocalCache\local-packages\Python310\site-packages\pandas\core\strings\accessor.py", line 129, in wrapper
    return func(self, *args, **kwargs)
TypeError: StringMethods.replace() missing 1 required positional argument: 'repl'
2023-05-18 23:41:27,386 - ERROR - Se ha presentado una excepcion: Can only use .str accessor with string values!
Traceback (most recent call last):
  File "C:\Users\alejo\AppData\Local\Temp\ipykernel_8984\3984319801.py", line 6, in <module>
    df['DISTANCE']=df['DISTANCE'].str.replace(' miles', '')
  File "C:\Users\alejo\AppData\Local\Packages\PythonSoftwareFoundation.Python.3.10_qbz5n2kfra8p0\LocalCache\local-packages\Python310\site-packages\pandas\core\generic.py", line 5902, in __getattr__
    return object.__getattribute__(self, name)
  File "C:\Users\alejo\AppData\Local\Packages\PythonSoftwareFoundation.Python.3.10_qbz5n2kfra8p0\LocalCache\local-packages\Python310\site-packages\pandas\core\accessor.py", line 182, in __get__
    accessor_obj = self._accessor(obj)
  File "C:\Users\alejo\AppData\Local\Packages\PythonSoftwareFoundation.Python.3.10_qbz5n2kfra8p0\LocalCache\local-packages\Python310\site-packages\pandas\core\strings\accessor.py", line 181, in __init__
    self._inferred_dtype = self._validate(data)
  File "C:\Users\alejo\AppData\Local\Packages\PythonSoftwareFoundation.Python.3.10_qbz5n2kfra8p0\LocalCache\local-packages\Python310\site-packages\pandas\core\strings\accessor.py", line 235, in _validate
    raise AttributeError("Can only use .str accessor with string values!")
AttributeError: Can only use .str accessor with string values!
2023-05-18 23:41:27,386 - ERROR - Se ha presentado una excepcion: Can only use .str accessor with string values!
Traceback (most recent call last):
  File "C:\Users\alejo\AppData\Local\Temp\ipykernel_8984\3984319801.py", line 6, in <module>
    df['DISTANCE']=df['DISTANCE'].str.replace(' miles', '')
  File "C:\Users\alejo\AppData\Local\Packages\PythonSoftwareFoundation.Python.3.10_qbz5n2kfra8p0\LocalCache\local-packages\Python310\site-packages\pandas\core\generic.py", line 5902, in __getattr__
    return object.__getattribute__(self, name)
  File "C:\Users\alejo\AppData\Local\Packages\PythonSoftwareFoundation.Python.3.10_qbz5n2kfra8p0\LocalCache\local-packages\Python310\site-packages\pandas\core\accessor.py", line 182, in __get__
    accessor_obj = self._accessor(obj)
  File "C:\Users\alejo\AppData\Local\Packages\PythonSoftwareFoundation.Python.3.10_qbz5n2kfra8p0\LocalCache\local-packages\Python310\site-packages\pandas\core\strings\accessor.py", line 181, in __init__
    self._inferred_dtype = self._validate(data)
  File "C:\Users\alejo\AppData\Local\Packages\PythonSoftwareFoundation.Python.3.10_qbz5n2kfra8p0\LocalCache\local-packages\Python310\site-packages\pandas\core\strings\accessor.py", line 235, in _validate
    raise AttributeError("Can only use .str accessor with string values!")
AttributeError: Can only use .str accessor with string values!
2023-05-18 23:43:08,192 - ERROR - Se ha presentado una excepcion: Can only use .str accessor with string values!
Traceback (most recent call last):
  File "C:\Users\alejo\AppData\Local\Temp\ipykernel_8984\3771178491.py", line 6, in <module>
    df['DISTANCE']=df['DISTANCE'].str.replace(' miles', '')
  File "C:\Users\alejo\AppData\Local\Packages\PythonSoftwareFoundation.Python.3.10_qbz5n2kfra8p0\LocalCache\local-packages\Python310\site-packages\pandas\core\generic.py", line 5902, in __getattr__
    return object.__getattribute__(self, name)
  File "C:\Users\alejo\AppData\Local\Packages\PythonSoftwareFoundation.Python.3.10_qbz5n2kfra8p0\LocalCache\local-packages\Python310\site-packages\pandas\core\accessor.py", line 182, in __get__
    accessor_obj = self._accessor(obj)
  File "C:\Users\alejo\AppData\Local\Packages\PythonSoftwareFoundation.Python.3.10_qbz5n2kfra8p0\LocalCache\local-packages\Python310\site-packages\pandas\core\strings\accessor.py", line 181, in __init__
    self._inferred_dtype = self._validate(data)
  File "C:\Users\alejo\AppData\Local\Packages\PythonSoftwareFoundation.Python.3.10_qbz5n2kfra8p0\LocalCache\local-packages\Python310\site-packages\pandas\core\strings\accessor.py", line 235, in _validate
    raise AttributeError("Can only use .str accessor with string values!")
AttributeError: Can only use .str accessor with string values!
2023-05-18 23:43:08,192 - ERROR - Se ha presentado una excepcion: Can only use .str accessor with string values!
Traceback (most recent call last):
  File "C:\Users\alejo\AppData\Local\Temp\ipykernel_8984\3771178491.py", line 6, in <module>
    df['DISTANCE']=df['DISTANCE'].str.replace(' miles', '')
  File "C:\Users\alejo\AppData\Local\Packages\PythonSoftwareFoundation.Python.3.10_qbz5n2kfra8p0\LocalCache\local-packages\Python310\site-packages\pandas\core\generic.py", line 5902, in __getattr__
    return object.__getattribute__(self, name)
  File "C:\Users\alejo\AppData\Local\Packages\PythonSoftwareFoundation.Python.3.10_qbz5n2kfra8p0\LocalCache\local-packages\Python310\site-packages\pandas\core\accessor.py", line 182, in __get__
    accessor_obj = self._accessor(obj)
  File "C:\Users\alejo\AppData\Local\Packages\PythonSoftwareFoundation.Python.3.10_qbz5n2kfra8p0\LocalCache\local-packages\Python310\site-packages\pandas\core\strings\accessor.py", line 181, in __init__
    self._inferred_dtype = self._validate(data)
  File "C:\Users\alejo\AppData\Local\Packages\PythonSoftwareFoundation.Python.3.10_qbz5n2kfra8p0\LocalCache\local-packages\Python310\site-packages\pandas\core\strings\accessor.py", line 235, in _validate
    raise AttributeError("Can only use .str accessor with string values!")
AttributeError: Can only use .str accessor with string values!
2023-05-18 23:43:08,192 - ERROR - Se ha presentado una excepcion: Can only use .str accessor with string values!
Traceback (most recent call last):
  File "C:\Users\alejo\AppData\Local\Temp\ipykernel_8984\3771178491.py", line 6, in <module>
    df['DISTANCE']=df['DISTANCE'].str.replace(' miles', '')
  File "C:\Users\alejo\AppData\Local\Packages\PythonSoftwareFoundation.Python.3.10_qbz5n2kfra8p0\LocalCache\local-packages\Python310\site-packages\pandas\core\generic.py", line 5902, in __getattr__
    return object.__getattribute__(self, name)
  File "C:\Users\alejo\AppData\Local\Packages\PythonSoftwareFoundation.Python.3.10_qbz5n2kfra8p0\LocalCache\local-packages\Python310\site-packages\pandas\core\accessor.py", line 182, in __get__
    accessor_obj = self._accessor(obj)
  File "C:\Users\alejo\AppData\Local\Packages\PythonSoftwareFoundation.Python.3.10_qbz5n2kfra8p0\LocalCache\local-packages\Python310\site-packages\pandas\core\strings\accessor.py", line 181, in __init__
    self._inferred_dtype = self._validate(data)
  File "C:\Users\alejo\AppData\Local\Packages\PythonSoftwareFoundation.Python.3.10_qbz5n2kfra8p0\LocalCache\local-packages\Python310\site-packages\pandas\core\strings\accessor.py", line 235, in _validate
    raise AttributeError("Can only use .str accessor with string values!")
AttributeError: Can only use .str accessor with string values!
2023-05-18 23:43:08,192 - ERROR - Se ha presentado una excepcion: Can only use .str accessor with string values!
Traceback (most recent call last):
  File "C:\Users\alejo\AppData\Local\Temp\ipykernel_8984\3771178491.py", line 6, in <module>
    df['DISTANCE']=df['DISTANCE'].str.replace(' miles', '')
  File "C:\Users\alejo\AppData\Local\Packages\PythonSoftwareFoundation.Python.3.10_qbz5n2kfra8p0\LocalCache\local-packages\Python310\site-packages\pandas\core\generic.py", line 5902, in __getattr__
    return object.__getattribute__(self, name)
  File "C:\Users\alejo\AppData\Local\Packages\PythonSoftwareFoundation.Python.3.10_qbz5n2kfra8p0\LocalCache\local-packages\Python310\site-packages\pandas\core\accessor.py", line 182, in __get__
    accessor_obj = self._accessor(obj)
  File "C:\Users\alejo\AppData\Local\Packages\PythonSoftwareFoundation.Python.3.10_qbz5n2kfra8p0\LocalCache\local-packages\Python310\site-packages\pandas\core\strings\accessor.py", line 181, in __init__
    self._inferred_dtype = self._validate(data)
  File "C:\Users\alejo\AppData\Local\Packages\PythonSoftwareFoundation.Python.3.10_qbz5n2kfra8p0\LocalCache\local-packages\Python310\site-packages\pandas\core\strings\accessor.py", line 235, in _validate
    raise AttributeError("Can only use .str accessor with string values!")
AttributeError: Can only use .str accessor with string values!
2023-05-18 23:44:21,373 - ERROR - Se ha presentado una excepcion: Need to pass bool-like values
Traceback (most recent call last):
  File "C:\Users\alejo\AppData\Local\Temp\ipykernel_8984\2559024290.py", line 17, in <module>
    df['DIVERTED']=df['DIVERTED'].astype('boolean')
  File "C:\Users\alejo\AppData\Local\Packages\PythonSoftwareFoundation.Python.3.10_qbz5n2kfra8p0\LocalCache\local-packages\Python310\site-packages\pandas\core\generic.py", line 6240, in astype
    new_data = self._mgr.astype(dtype=dtype, copy=copy, errors=errors)
  File "C:\Users\alejo\AppData\Local\Packages\PythonSoftwareFoundation.Python.3.10_qbz5n2kfra8p0\LocalCache\local-packages\Python310\site-packages\pandas\core\internals\managers.py", line 448, in astype
    return self.apply("astype", dtype=dtype, copy=copy, errors=errors)
  File "C:\Users\alejo\AppData\Local\Packages\PythonSoftwareFoundation.Python.3.10_qbz5n2kfra8p0\LocalCache\local-packages\Python310\site-packages\pandas\core\internals\managers.py", line 352, in apply
    applied = getattr(b, f)(**kwargs)
  File "C:\Users\alejo\AppData\Local\Packages\PythonSoftwareFoundation.Python.3.10_qbz5n2kfra8p0\LocalCache\local-packages\Python310\site-packages\pandas\core\internals\blocks.py", line 526, in astype
    new_values = astype_array_safe(values, dtype, copy=copy, errors=errors)
  File "C:\Users\alejo\AppData\Local\Packages\PythonSoftwareFoundation.Python.3.10_qbz5n2kfra8p0\LocalCache\local-packages\Python310\site-packages\pandas\core\dtypes\astype.py", line 299, in astype_array_safe
    new_values = astype_array(values, dtype, copy=copy)
  File "C:\Users\alejo\AppData\Local\Packages\PythonSoftwareFoundation.Python.3.10_qbz5n2kfra8p0\LocalCache\local-packages\Python310\site-packages\pandas\core\dtypes\astype.py", line 230, in astype_array
    values = astype_nansafe(values, dtype, copy=copy)
  File "C:\Users\alejo\AppData\Local\Packages\PythonSoftwareFoundation.Python.3.10_qbz5n2kfra8p0\LocalCache\local-packages\Python310\site-packages\pandas\core\dtypes\astype.py", line 95, in astype_nansafe
    return dtype.construct_array_type()._from_sequence(arr, dtype=dtype, copy=copy)
  File "C:\Users\alejo\AppData\Local\Packages\PythonSoftwareFoundation.Python.3.10_qbz5n2kfra8p0\LocalCache\local-packages\Python310\site-packages\pandas\core\arrays\masked.py", line 132, in _from_sequence
    values, mask = cls._coerce_to_array(scalars, dtype=dtype, copy=copy)
  File "C:\Users\alejo\AppData\Local\Packages\PythonSoftwareFoundation.Python.3.10_qbz5n2kfra8p0\LocalCache\local-packages\Python310\site-packages\pandas\core\arrays\boolean.py", line 344, in _coerce_to_array
    return coerce_to_array(value, copy=copy)
  File "C:\Users\alejo\AppData\Local\Packages\PythonSoftwareFoundation.Python.3.10_qbz5n2kfra8p0\LocalCache\local-packages\Python310\site-packages\pandas\core\arrays\boolean.py", line 194, in coerce_to_array
    raise TypeError("Need to pass bool-like values")
TypeError: Need to pass bool-like values
2023-05-18 23:44:21,373 - ERROR - Se ha presentado una excepcion: Need to pass bool-like values
Traceback (most recent call last):
  File "C:\Users\alejo\AppData\Local\Temp\ipykernel_8984\2559024290.py", line 17, in <module>
    df['DIVERTED']=df['DIVERTED'].astype('boolean')
  File "C:\Users\alejo\AppData\Local\Packages\PythonSoftwareFoundation.Python.3.10_qbz5n2kfra8p0\LocalCache\local-packages\Python310\site-packages\pandas\core\generic.py", line 6240, in astype
    new_data = self._mgr.astype(dtype=dtype, copy=copy, errors=errors)
  File "C:\Users\alejo\AppData\Local\Packages\PythonSoftwareFoundation.Python.3.10_qbz5n2kfra8p0\LocalCache\local-packages\Python310\site-packages\pandas\core\internals\managers.py", line 448, in astype
    return self.apply("astype", dtype=dtype, copy=copy, errors=errors)
  File "C:\Users\alejo\AppData\Local\Packages\PythonSoftwareFoundation.Python.3.10_qbz5n2kfra8p0\LocalCache\local-packages\Python310\site-packages\pandas\core\internals\managers.py", line 352, in apply
    applied = getattr(b, f)(**kwargs)
  File "C:\Users\alejo\AppData\Local\Packages\PythonSoftwareFoundation.Python.3.10_qbz5n2kfra8p0\LocalCache\local-packages\Python310\site-packages\pandas\core\internals\blocks.py", line 526, in astype
    new_values = astype_array_safe(values, dtype, copy=copy, errors=errors)
  File "C:\Users\alejo\AppData\Local\Packages\PythonSoftwareFoundation.Python.3.10_qbz5n2kfra8p0\LocalCache\local-packages\Python310\site-packages\pandas\core\dtypes\astype.py", line 299, in astype_array_safe
    new_values = astype_array(values, dtype, copy=copy)
  File "C:\Users\alejo\AppData\Local\Packages\PythonSoftwareFoundation.Python.3.10_qbz5n2kfra8p0\LocalCache\local-packages\Python310\site-packages\pandas\core\dtypes\astype.py", line 230, in astype_array
    values = astype_nansafe(values, dtype, copy=copy)
  File "C:\Users\alejo\AppData\Local\Packages\PythonSoftwareFoundation.Python.3.10_qbz5n2kfra8p0\LocalCache\local-packages\Python310\site-packages\pandas\core\dtypes\astype.py", line 95, in astype_nansafe
    return dtype.construct_array_type()._from_sequence(arr, dtype=dtype, copy=copy)
  File "C:\Users\alejo\AppData\Local\Packages\PythonSoftwareFoundation.Python.3.10_qbz5n2kfra8p0\LocalCache\local-packages\Python310\site-packages\pandas\core\arrays\masked.py", line 132, in _from_sequence
    values, mask = cls._coerce_to_array(scalars, dtype=dtype, copy=copy)
  File "C:\Users\alejo\AppData\Local\Packages\PythonSoftwareFoundation.Python.3.10_qbz5n2kfra8p0\LocalCache\local-packages\Python310\site-packages\pandas\core\arrays\boolean.py", line 344, in _coerce_to_array
    return coerce_to_array(value, copy=copy)
  File "C:\Users\alejo\AppData\Local\Packages\PythonSoftwareFoundation.Python.3.10_qbz5n2kfra8p0\LocalCache\local-packages\Python310\site-packages\pandas\core\arrays\boolean.py", line 194, in coerce_to_array
    raise TypeError("Need to pass bool-like values")
TypeError: Need to pass bool-like values
2023-05-18 23:44:21,373 - ERROR - Se ha presentado una excepcion: Need to pass bool-like values
Traceback (most recent call last):
  File "C:\Users\alejo\AppData\Local\Temp\ipykernel_8984\2559024290.py", line 17, in <module>
    df['DIVERTED']=df['DIVERTED'].astype('boolean')
  File "C:\Users\alejo\AppData\Local\Packages\PythonSoftwareFoundation.Python.3.10_qbz5n2kfra8p0\LocalCache\local-packages\Python310\site-packages\pandas\core\generic.py", line 6240, in astype
    new_data = self._mgr.astype(dtype=dtype, copy=copy, errors=errors)
  File "C:\Users\alejo\AppData\Local\Packages\PythonSoftwareFoundation.Python.3.10_qbz5n2kfra8p0\LocalCache\local-packages\Python310\site-packages\pandas\core\internals\managers.py", line 448, in astype
    return self.apply("astype", dtype=dtype, copy=copy, errors=errors)
  File "C:\Users\alejo\AppData\Local\Packages\PythonSoftwareFoundation.Python.3.10_qbz5n2kfra8p0\LocalCache\local-packages\Python310\site-packages\pandas\core\internals\managers.py", line 352, in apply
    applied = getattr(b, f)(**kwargs)
  File "C:\Users\alejo\AppData\Local\Packages\PythonSoftwareFoundation.Python.3.10_qbz5n2kfra8p0\LocalCache\local-packages\Python310\site-packages\pandas\core\internals\blocks.py", line 526, in astype
    new_values = astype_array_safe(values, dtype, copy=copy, errors=errors)
  File "C:\Users\alejo\AppData\Local\Packages\PythonSoftwareFoundation.Python.3.10_qbz5n2kfra8p0\LocalCache\local-packages\Python310\site-packages\pandas\core\dtypes\astype.py", line 299, in astype_array_safe
    new_values = astype_array(values, dtype, copy=copy)
  File "C:\Users\alejo\AppData\Local\Packages\PythonSoftwareFoundation.Python.3.10_qbz5n2kfra8p0\LocalCache\local-packages\Python310\site-packages\pandas\core\dtypes\astype.py", line 230, in astype_array
    values = astype_nansafe(values, dtype, copy=copy)
  File "C:\Users\alejo\AppData\Local\Packages\PythonSoftwareFoundation.Python.3.10_qbz5n2kfra8p0\LocalCache\local-packages\Python310\site-packages\pandas\core\dtypes\astype.py", line 95, in astype_nansafe
    return dtype.construct_array_type()._from_sequence(arr, dtype=dtype, copy=copy)
  File "C:\Users\alejo\AppData\Local\Packages\PythonSoftwareFoundation.Python.3.10_qbz5n2kfra8p0\LocalCache\local-packages\Python310\site-packages\pandas\core\arrays\masked.py", line 132, in _from_sequence
    values, mask = cls._coerce_to_array(scalars, dtype=dtype, copy=copy)
  File "C:\Users\alejo\AppData\Local\Packages\PythonSoftwareFoundation.Python.3.10_qbz5n2kfra8p0\LocalCache\local-packages\Python310\site-packages\pandas\core\arrays\boolean.py", line 344, in _coerce_to_array
    return coerce_to_array(value, copy=copy)
  File "C:\Users\alejo\AppData\Local\Packages\PythonSoftwareFoundation.Python.3.10_qbz5n2kfra8p0\LocalCache\local-packages\Python310\site-packages\pandas\core\arrays\boolean.py", line 194, in coerce_to_array
    raise TypeError("Need to pass bool-like values")
TypeError: Need to pass bool-like values
2023-05-18 23:44:21,373 - ERROR - Se ha presentado una excepcion: Need to pass bool-like values
Traceback (most recent call last):
  File "C:\Users\alejo\AppData\Local\Temp\ipykernel_8984\2559024290.py", line 17, in <module>
    df['DIVERTED']=df['DIVERTED'].astype('boolean')
  File "C:\Users\alejo\AppData\Local\Packages\PythonSoftwareFoundation.Python.3.10_qbz5n2kfra8p0\LocalCache\local-packages\Python310\site-packages\pandas\core\generic.py", line 6240, in astype
    new_data = self._mgr.astype(dtype=dtype, copy=copy, errors=errors)
  File "C:\Users\alejo\AppData\Local\Packages\PythonSoftwareFoundation.Python.3.10_qbz5n2kfra8p0\LocalCache\local-packages\Python310\site-packages\pandas\core\internals\managers.py", line 448, in astype
    return self.apply("astype", dtype=dtype, copy=copy, errors=errors)
  File "C:\Users\alejo\AppData\Local\Packages\PythonSoftwareFoundation.Python.3.10_qbz5n2kfra8p0\LocalCache\local-packages\Python310\site-packages\pandas\core\internals\managers.py", line 352, in apply
    applied = getattr(b, f)(**kwargs)
  File "C:\Users\alejo\AppData\Local\Packages\PythonSoftwareFoundation.Python.3.10_qbz5n2kfra8p0\LocalCache\local-packages\Python310\site-packages\pandas\core\internals\blocks.py", line 526, in astype
    new_values = astype_array_safe(values, dtype, copy=copy, errors=errors)
  File "C:\Users\alejo\AppData\Local\Packages\PythonSoftwareFoundation.Python.3.10_qbz5n2kfra8p0\LocalCache\local-packages\Python310\site-packages\pandas\core\dtypes\astype.py", line 299, in astype_array_safe
    new_values = astype_array(values, dtype, copy=copy)
  File "C:\Users\alejo\AppData\Local\Packages\PythonSoftwareFoundation.Python.3.10_qbz5n2kfra8p0\LocalCache\local-packages\Python310\site-packages\pandas\core\dtypes\astype.py", line 230, in astype_array
    values = astype_nansafe(values, dtype, copy=copy)
  File "C:\Users\alejo\AppData\Local\Packages\PythonSoftwareFoundation.Python.3.10_qbz5n2kfra8p0\LocalCache\local-packages\Python310\site-packages\pandas\core\dtypes\astype.py", line 95, in astype_nansafe
    return dtype.construct_array_type()._from_sequence(arr, dtype=dtype, copy=copy)
  File "C:\Users\alejo\AppData\Local\Packages\PythonSoftwareFoundation.Python.3.10_qbz5n2kfra8p0\LocalCache\local-packages\Python310\site-packages\pandas\core\arrays\masked.py", line 132, in _from_sequence
    values, mask = cls._coerce_to_array(scalars, dtype=dtype, copy=copy)
  File "C:\Users\alejo\AppData\Local\Packages\PythonSoftwareFoundation.Python.3.10_qbz5n2kfra8p0\LocalCache\local-packages\Python310\site-packages\pandas\core\arrays\boolean.py", line 344, in _coerce_to_array
    return coerce_to_array(value, copy=copy)
  File "C:\Users\alejo\AppData\Local\Packages\PythonSoftwareFoundation.Python.3.10_qbz5n2kfra8p0\LocalCache\local-packages\Python310\site-packages\pandas\core\arrays\boolean.py", line 194, in coerce_to_array
    raise TypeError("Need to pass bool-like values")
TypeError: Need to pass bool-like values
2023-05-18 23:44:21,373 - ERROR - Se ha presentado una excepcion: Need to pass bool-like values
Traceback (most recent call last):
  File "C:\Users\alejo\AppData\Local\Temp\ipykernel_8984\2559024290.py", line 17, in <module>
    df['DIVERTED']=df['DIVERTED'].astype('boolean')
  File "C:\Users\alejo\AppData\Local\Packages\PythonSoftwareFoundation.Python.3.10_qbz5n2kfra8p0\LocalCache\local-packages\Python310\site-packages\pandas\core\generic.py", line 6240, in astype
    new_data = self._mgr.astype(dtype=dtype, copy=copy, errors=errors)
  File "C:\Users\alejo\AppData\Local\Packages\PythonSoftwareFoundation.Python.3.10_qbz5n2kfra8p0\LocalCache\local-packages\Python310\site-packages\pandas\core\internals\managers.py", line 448, in astype
    return self.apply("astype", dtype=dtype, copy=copy, errors=errors)
  File "C:\Users\alejo\AppData\Local\Packages\PythonSoftwareFoundation.Python.3.10_qbz5n2kfra8p0\LocalCache\local-packages\Python310\site-packages\pandas\core\internals\managers.py", line 352, in apply
    applied = getattr(b, f)(**kwargs)
  File "C:\Users\alejo\AppData\Local\Packages\PythonSoftwareFoundation.Python.3.10_qbz5n2kfra8p0\LocalCache\local-packages\Python310\site-packages\pandas\core\internals\blocks.py", line 526, in astype
    new_values = astype_array_safe(values, dtype, copy=copy, errors=errors)
  File "C:\Users\alejo\AppData\Local\Packages\PythonSoftwareFoundation.Python.3.10_qbz5n2kfra8p0\LocalCache\local-packages\Python310\site-packages\pandas\core\dtypes\astype.py", line 299, in astype_array_safe
    new_values = astype_array(values, dtype, copy=copy)
  File "C:\Users\alejo\AppData\Local\Packages\PythonSoftwareFoundation.Python.3.10_qbz5n2kfra8p0\LocalCache\local-packages\Python310\site-packages\pandas\core\dtypes\astype.py", line 230, in astype_array
    values = astype_nansafe(values, dtype, copy=copy)
  File "C:\Users\alejo\AppData\Local\Packages\PythonSoftwareFoundation.Python.3.10_qbz5n2kfra8p0\LocalCache\local-packages\Python310\site-packages\pandas\core\dtypes\astype.py", line 95, in astype_nansafe
    return dtype.construct_array_type()._from_sequence(arr, dtype=dtype, copy=copy)
  File "C:\Users\alejo\AppData\Local\Packages\PythonSoftwareFoundation.Python.3.10_qbz5n2kfra8p0\LocalCache\local-packages\Python310\site-packages\pandas\core\arrays\masked.py", line 132, in _from_sequence
    values, mask = cls._coerce_to_array(scalars, dtype=dtype, copy=copy)
  File "C:\Users\alejo\AppData\Local\Packages\PythonSoftwareFoundation.Python.3.10_qbz5n2kfra8p0\LocalCache\local-packages\Python310\site-packages\pandas\core\arrays\boolean.py", line 344, in _coerce_to_array
    return coerce_to_array(value, copy=copy)
  File "C:\Users\alejo\AppData\Local\Packages\PythonSoftwareFoundation.Python.3.10_qbz5n2kfra8p0\LocalCache\local-packages\Python310\site-packages\pandas\core\arrays\boolean.py", line 194, in coerce_to_array
    raise TypeError("Need to pass bool-like values")
TypeError: Need to pass bool-like values
2023-05-18 23:44:21,373 - ERROR - Se ha presentado una excepcion: Need to pass bool-like values
Traceback (most recent call last):
  File "C:\Users\alejo\AppData\Local\Temp\ipykernel_8984\2559024290.py", line 17, in <module>
    df['DIVERTED']=df['DIVERTED'].astype('boolean')
  File "C:\Users\alejo\AppData\Local\Packages\PythonSoftwareFoundation.Python.3.10_qbz5n2kfra8p0\LocalCache\local-packages\Python310\site-packages\pandas\core\generic.py", line 6240, in astype
    new_data = self._mgr.astype(dtype=dtype, copy=copy, errors=errors)
  File "C:\Users\alejo\AppData\Local\Packages\PythonSoftwareFoundation.Python.3.10_qbz5n2kfra8p0\LocalCache\local-packages\Python310\site-packages\pandas\core\internals\managers.py", line 448, in astype
    return self.apply("astype", dtype=dtype, copy=copy, errors=errors)
  File "C:\Users\alejo\AppData\Local\Packages\PythonSoftwareFoundation.Python.3.10_qbz5n2kfra8p0\LocalCache\local-packages\Python310\site-packages\pandas\core\internals\managers.py", line 352, in apply
    applied = getattr(b, f)(**kwargs)
  File "C:\Users\alejo\AppData\Local\Packages\PythonSoftwareFoundation.Python.3.10_qbz5n2kfra8p0\LocalCache\local-packages\Python310\site-packages\pandas\core\internals\blocks.py", line 526, in astype
    new_values = astype_array_safe(values, dtype, copy=copy, errors=errors)
  File "C:\Users\alejo\AppData\Local\Packages\PythonSoftwareFoundation.Python.3.10_qbz5n2kfra8p0\LocalCache\local-packages\Python310\site-packages\pandas\core\dtypes\astype.py", line 299, in astype_array_safe
    new_values = astype_array(values, dtype, copy=copy)
  File "C:\Users\alejo\AppData\Local\Packages\PythonSoftwareFoundation.Python.3.10_qbz5n2kfra8p0\LocalCache\local-packages\Python310\site-packages\pandas\core\dtypes\astype.py", line 230, in astype_array
    values = astype_nansafe(values, dtype, copy=copy)
  File "C:\Users\alejo\AppData\Local\Packages\PythonSoftwareFoundation.Python.3.10_qbz5n2kfra8p0\LocalCache\local-packages\Python310\site-packages\pandas\core\dtypes\astype.py", line 95, in astype_nansafe
    return dtype.construct_array_type()._from_sequence(arr, dtype=dtype, copy=copy)
  File "C:\Users\alejo\AppData\Local\Packages\PythonSoftwareFoundation.Python.3.10_qbz5n2kfra8p0\LocalCache\local-packages\Python310\site-packages\pandas\core\arrays\masked.py", line 132, in _from_sequence
    values, mask = cls._coerce_to_array(scalars, dtype=dtype, copy=copy)
  File "C:\Users\alejo\AppData\Local\Packages\PythonSoftwareFoundation.Python.3.10_qbz5n2kfra8p0\LocalCache\local-packages\Python310\site-packages\pandas\core\arrays\boolean.py", line 344, in _coerce_to_array
    return coerce_to_array(value, copy=copy)
  File "C:\Users\alejo\AppData\Local\Packages\PythonSoftwareFoundation.Python.3.10_qbz5n2kfra8p0\LocalCache\local-packages\Python310\site-packages\pandas\core\arrays\boolean.py", line 194, in coerce_to_array
    raise TypeError("Need to pass bool-like values")
TypeError: Need to pass bool-like values
2023-05-18 23:45:33,882 - ERROR - Se ha presentado una excepcion: Need to pass bool-like values
Traceback (most recent call last):
  File "C:\Users\alejo\AppData\Local\Temp\ipykernel_8984\4051536291.py", line 17, in <module>
    df['DIVERTED']=df['DIVERTED'].astype('boolean')
  File "C:\Users\alejo\AppData\Local\Packages\PythonSoftwareFoundation.Python.3.10_qbz5n2kfra8p0\LocalCache\local-packages\Python310\site-packages\pandas\core\generic.py", line 6240, in astype
    new_data = self._mgr.astype(dtype=dtype, copy=copy, errors=errors)
  File "C:\Users\alejo\AppData\Local\Packages\PythonSoftwareFoundation.Python.3.10_qbz5n2kfra8p0\LocalCache\local-packages\Python310\site-packages\pandas\core\internals\managers.py", line 448, in astype
    return self.apply("astype", dtype=dtype, copy=copy, errors=errors)
  File "C:\Users\alejo\AppData\Local\Packages\PythonSoftwareFoundation.Python.3.10_qbz5n2kfra8p0\LocalCache\local-packages\Python310\site-packages\pandas\core\internals\managers.py", line 352, in apply
    applied = getattr(b, f)(**kwargs)
  File "C:\Users\alejo\AppData\Local\Packages\PythonSoftwareFoundation.Python.3.10_qbz5n2kfra8p0\LocalCache\local-packages\Python310\site-packages\pandas\core\internals\blocks.py", line 526, in astype
    new_values = astype_array_safe(values, dtype, copy=copy, errors=errors)
  File "C:\Users\alejo\AppData\Local\Packages\PythonSoftwareFoundation.Python.3.10_qbz5n2kfra8p0\LocalCache\local-packages\Python310\site-packages\pandas\core\dtypes\astype.py", line 299, in astype_array_safe
    new_values = astype_array(values, dtype, copy=copy)
  File "C:\Users\alejo\AppData\Local\Packages\PythonSoftwareFoundation.Python.3.10_qbz5n2kfra8p0\LocalCache\local-packages\Python310\site-packages\pandas\core\dtypes\astype.py", line 230, in astype_array
    values = astype_nansafe(values, dtype, copy=copy)
  File "C:\Users\alejo\AppData\Local\Packages\PythonSoftwareFoundation.Python.3.10_qbz5n2kfra8p0\LocalCache\local-packages\Python310\site-packages\pandas\core\dtypes\astype.py", line 95, in astype_nansafe
    return dtype.construct_array_type()._from_sequence(arr, dtype=dtype, copy=copy)
  File "C:\Users\alejo\AppData\Local\Packages\PythonSoftwareFoundation.Python.3.10_qbz5n2kfra8p0\LocalCache\local-packages\Python310\site-packages\pandas\core\arrays\masked.py", line 132, in _from_sequence
    values, mask = cls._coerce_to_array(scalars, dtype=dtype, copy=copy)
  File "C:\Users\alejo\AppData\Local\Packages\PythonSoftwareFoundation.Python.3.10_qbz5n2kfra8p0\LocalCache\local-packages\Python310\site-packages\pandas\core\arrays\boolean.py", line 344, in _coerce_to_array
    return coerce_to_array(value, copy=copy)
  File "C:\Users\alejo\AppData\Local\Packages\PythonSoftwareFoundation.Python.3.10_qbz5n2kfra8p0\LocalCache\local-packages\Python310\site-packages\pandas\core\arrays\boolean.py", line 194, in coerce_to_array
    raise TypeError("Need to pass bool-like values")
TypeError: Need to pass bool-like values
2023-05-18 23:45:33,882 - ERROR - Se ha presentado una excepcion: Need to pass bool-like values
Traceback (most recent call last):
  File "C:\Users\alejo\AppData\Local\Temp\ipykernel_8984\4051536291.py", line 17, in <module>
    df['DIVERTED']=df['DIVERTED'].astype('boolean')
  File "C:\Users\alejo\AppData\Local\Packages\PythonSoftwareFoundation.Python.3.10_qbz5n2kfra8p0\LocalCache\local-packages\Python310\site-packages\pandas\core\generic.py", line 6240, in astype
    new_data = self._mgr.astype(dtype=dtype, copy=copy, errors=errors)
  File "C:\Users\alejo\AppData\Local\Packages\PythonSoftwareFoundation.Python.3.10_qbz5n2kfra8p0\LocalCache\local-packages\Python310\site-packages\pandas\core\internals\managers.py", line 448, in astype
    return self.apply("astype", dtype=dtype, copy=copy, errors=errors)
  File "C:\Users\alejo\AppData\Local\Packages\PythonSoftwareFoundation.Python.3.10_qbz5n2kfra8p0\LocalCache\local-packages\Python310\site-packages\pandas\core\internals\managers.py", line 352, in apply
    applied = getattr(b, f)(**kwargs)
  File "C:\Users\alejo\AppData\Local\Packages\PythonSoftwareFoundation.Python.3.10_qbz5n2kfra8p0\LocalCache\local-packages\Python310\site-packages\pandas\core\internals\blocks.py", line 526, in astype
    new_values = astype_array_safe(values, dtype, copy=copy, errors=errors)
  File "C:\Users\alejo\AppData\Local\Packages\PythonSoftwareFoundation.Python.3.10_qbz5n2kfra8p0\LocalCache\local-packages\Python310\site-packages\pandas\core\dtypes\astype.py", line 299, in astype_array_safe
    new_values = astype_array(values, dtype, copy=copy)
  File "C:\Users\alejo\AppData\Local\Packages\PythonSoftwareFoundation.Python.3.10_qbz5n2kfra8p0\LocalCache\local-packages\Python310\site-packages\pandas\core\dtypes\astype.py", line 230, in astype_array
    values = astype_nansafe(values, dtype, copy=copy)
  File "C:\Users\alejo\AppData\Local\Packages\PythonSoftwareFoundation.Python.3.10_qbz5n2kfra8p0\LocalCache\local-packages\Python310\site-packages\pandas\core\dtypes\astype.py", line 95, in astype_nansafe
    return dtype.construct_array_type()._from_sequence(arr, dtype=dtype, copy=copy)
  File "C:\Users\alejo\AppData\Local\Packages\PythonSoftwareFoundation.Python.3.10_qbz5n2kfra8p0\LocalCache\local-packages\Python310\site-packages\pandas\core\arrays\masked.py", line 132, in _from_sequence
    values, mask = cls._coerce_to_array(scalars, dtype=dtype, copy=copy)
  File "C:\Users\alejo\AppData\Local\Packages\PythonSoftwareFoundation.Python.3.10_qbz5n2kfra8p0\LocalCache\local-packages\Python310\site-packages\pandas\core\arrays\boolean.py", line 344, in _coerce_to_array
    return coerce_to_array(value, copy=copy)
  File "C:\Users\alejo\AppData\Local\Packages\PythonSoftwareFoundation.Python.3.10_qbz5n2kfra8p0\LocalCache\local-packages\Python310\site-packages\pandas\core\arrays\boolean.py", line 194, in coerce_to_array
    raise TypeError("Need to pass bool-like values")
TypeError: Need to pass bool-like values
2023-05-18 23:45:33,882 - ERROR - Se ha presentado una excepcion: Need to pass bool-like values
Traceback (most recent call last):
  File "C:\Users\alejo\AppData\Local\Temp\ipykernel_8984\4051536291.py", line 17, in <module>
    df['DIVERTED']=df['DIVERTED'].astype('boolean')
  File "C:\Users\alejo\AppData\Local\Packages\PythonSoftwareFoundation.Python.3.10_qbz5n2kfra8p0\LocalCache\local-packages\Python310\site-packages\pandas\core\generic.py", line 6240, in astype
    new_data = self._mgr.astype(dtype=dtype, copy=copy, errors=errors)
  File "C:\Users\alejo\AppData\Local\Packages\PythonSoftwareFoundation.Python.3.10_qbz5n2kfra8p0\LocalCache\local-packages\Python310\site-packages\pandas\core\internals\managers.py", line 448, in astype
    return self.apply("astype", dtype=dtype, copy=copy, errors=errors)
  File "C:\Users\alejo\AppData\Local\Packages\PythonSoftwareFoundation.Python.3.10_qbz5n2kfra8p0\LocalCache\local-packages\Python310\site-packages\pandas\core\internals\managers.py", line 352, in apply
    applied = getattr(b, f)(**kwargs)
  File "C:\Users\alejo\AppData\Local\Packages\PythonSoftwareFoundation.Python.3.10_qbz5n2kfra8p0\LocalCache\local-packages\Python310\site-packages\pandas\core\internals\blocks.py", line 526, in astype
    new_values = astype_array_safe(values, dtype, copy=copy, errors=errors)
  File "C:\Users\alejo\AppData\Local\Packages\PythonSoftwareFoundation.Python.3.10_qbz5n2kfra8p0\LocalCache\local-packages\Python310\site-packages\pandas\core\dtypes\astype.py", line 299, in astype_array_safe
    new_values = astype_array(values, dtype, copy=copy)
  File "C:\Users\alejo\AppData\Local\Packages\PythonSoftwareFoundation.Python.3.10_qbz5n2kfra8p0\LocalCache\local-packages\Python310\site-packages\pandas\core\dtypes\astype.py", line 230, in astype_array
    values = astype_nansafe(values, dtype, copy=copy)
  File "C:\Users\alejo\AppData\Local\Packages\PythonSoftwareFoundation.Python.3.10_qbz5n2kfra8p0\LocalCache\local-packages\Python310\site-packages\pandas\core\dtypes\astype.py", line 95, in astype_nansafe
    return dtype.construct_array_type()._from_sequence(arr, dtype=dtype, copy=copy)
  File "C:\Users\alejo\AppData\Local\Packages\PythonSoftwareFoundation.Python.3.10_qbz5n2kfra8p0\LocalCache\local-packages\Python310\site-packages\pandas\core\arrays\masked.py", line 132, in _from_sequence
    values, mask = cls._coerce_to_array(scalars, dtype=dtype, copy=copy)
  File "C:\Users\alejo\AppData\Local\Packages\PythonSoftwareFoundation.Python.3.10_qbz5n2kfra8p0\LocalCache\local-packages\Python310\site-packages\pandas\core\arrays\boolean.py", line 344, in _coerce_to_array
    return coerce_to_array(value, copy=copy)
  File "C:\Users\alejo\AppData\Local\Packages\PythonSoftwareFoundation.Python.3.10_qbz5n2kfra8p0\LocalCache\local-packages\Python310\site-packages\pandas\core\arrays\boolean.py", line 194, in coerce_to_array
    raise TypeError("Need to pass bool-like values")
TypeError: Need to pass bool-like values
2023-05-18 23:45:33,882 - ERROR - Se ha presentado una excepcion: Need to pass bool-like values
Traceback (most recent call last):
  File "C:\Users\alejo\AppData\Local\Temp\ipykernel_8984\4051536291.py", line 17, in <module>
    df['DIVERTED']=df['DIVERTED'].astype('boolean')
  File "C:\Users\alejo\AppData\Local\Packages\PythonSoftwareFoundation.Python.3.10_qbz5n2kfra8p0\LocalCache\local-packages\Python310\site-packages\pandas\core\generic.py", line 6240, in astype
    new_data = self._mgr.astype(dtype=dtype, copy=copy, errors=errors)
  File "C:\Users\alejo\AppData\Local\Packages\PythonSoftwareFoundation.Python.3.10_qbz5n2kfra8p0\LocalCache\local-packages\Python310\site-packages\pandas\core\internals\managers.py", line 448, in astype
    return self.apply("astype", dtype=dtype, copy=copy, errors=errors)
  File "C:\Users\alejo\AppData\Local\Packages\PythonSoftwareFoundation.Python.3.10_qbz5n2kfra8p0\LocalCache\local-packages\Python310\site-packages\pandas\core\internals\managers.py", line 352, in apply
    applied = getattr(b, f)(**kwargs)
  File "C:\Users\alejo\AppData\Local\Packages\PythonSoftwareFoundation.Python.3.10_qbz5n2kfra8p0\LocalCache\local-packages\Python310\site-packages\pandas\core\internals\blocks.py", line 526, in astype
    new_values = astype_array_safe(values, dtype, copy=copy, errors=errors)
  File "C:\Users\alejo\AppData\Local\Packages\PythonSoftwareFoundation.Python.3.10_qbz5n2kfra8p0\LocalCache\local-packages\Python310\site-packages\pandas\core\dtypes\astype.py", line 299, in astype_array_safe
    new_values = astype_array(values, dtype, copy=copy)
  File "C:\Users\alejo\AppData\Local\Packages\PythonSoftwareFoundation.Python.3.10_qbz5n2kfra8p0\LocalCache\local-packages\Python310\site-packages\pandas\core\dtypes\astype.py", line 230, in astype_array
    values = astype_nansafe(values, dtype, copy=copy)
  File "C:\Users\alejo\AppData\Local\Packages\PythonSoftwareFoundation.Python.3.10_qbz5n2kfra8p0\LocalCache\local-packages\Python310\site-packages\pandas\core\dtypes\astype.py", line 95, in astype_nansafe
    return dtype.construct_array_type()._from_sequence(arr, dtype=dtype, copy=copy)
  File "C:\Users\alejo\AppData\Local\Packages\PythonSoftwareFoundation.Python.3.10_qbz5n2kfra8p0\LocalCache\local-packages\Python310\site-packages\pandas\core\arrays\masked.py", line 132, in _from_sequence
    values, mask = cls._coerce_to_array(scalars, dtype=dtype, copy=copy)
  File "C:\Users\alejo\AppData\Local\Packages\PythonSoftwareFoundation.Python.3.10_qbz5n2kfra8p0\LocalCache\local-packages\Python310\site-packages\pandas\core\arrays\boolean.py", line 344, in _coerce_to_array
    return coerce_to_array(value, copy=copy)
  File "C:\Users\alejo\AppData\Local\Packages\PythonSoftwareFoundation.Python.3.10_qbz5n2kfra8p0\LocalCache\local-packages\Python310\site-packages\pandas\core\arrays\boolean.py", line 194, in coerce_to_array
    raise TypeError("Need to pass bool-like values")
TypeError: Need to pass bool-like values
2023-05-18 23:45:33,882 - ERROR - Se ha presentado una excepcion: Need to pass bool-like values
Traceback (most recent call last):
  File "C:\Users\alejo\AppData\Local\Temp\ipykernel_8984\4051536291.py", line 17, in <module>
    df['DIVERTED']=df['DIVERTED'].astype('boolean')
  File "C:\Users\alejo\AppData\Local\Packages\PythonSoftwareFoundation.Python.3.10_qbz5n2kfra8p0\LocalCache\local-packages\Python310\site-packages\pandas\core\generic.py", line 6240, in astype
    new_data = self._mgr.astype(dtype=dtype, copy=copy, errors=errors)
  File "C:\Users\alejo\AppData\Local\Packages\PythonSoftwareFoundation.Python.3.10_qbz5n2kfra8p0\LocalCache\local-packages\Python310\site-packages\pandas\core\internals\managers.py", line 448, in astype
    return self.apply("astype", dtype=dtype, copy=copy, errors=errors)
  File "C:\Users\alejo\AppData\Local\Packages\PythonSoftwareFoundation.Python.3.10_qbz5n2kfra8p0\LocalCache\local-packages\Python310\site-packages\pandas\core\internals\managers.py", line 352, in apply
    applied = getattr(b, f)(**kwargs)
  File "C:\Users\alejo\AppData\Local\Packages\PythonSoftwareFoundation.Python.3.10_qbz5n2kfra8p0\LocalCache\local-packages\Python310\site-packages\pandas\core\internals\blocks.py", line 526, in astype
    new_values = astype_array_safe(values, dtype, copy=copy, errors=errors)
  File "C:\Users\alejo\AppData\Local\Packages\PythonSoftwareFoundation.Python.3.10_qbz5n2kfra8p0\LocalCache\local-packages\Python310\site-packages\pandas\core\dtypes\astype.py", line 299, in astype_array_safe
    new_values = astype_array(values, dtype, copy=copy)
  File "C:\Users\alejo\AppData\Local\Packages\PythonSoftwareFoundation.Python.3.10_qbz5n2kfra8p0\LocalCache\local-packages\Python310\site-packages\pandas\core\dtypes\astype.py", line 230, in astype_array
    values = astype_nansafe(values, dtype, copy=copy)
  File "C:\Users\alejo\AppData\Local\Packages\PythonSoftwareFoundation.Python.3.10_qbz5n2kfra8p0\LocalCache\local-packages\Python310\site-packages\pandas\core\dtypes\astype.py", line 95, in astype_nansafe
    return dtype.construct_array_type()._from_sequence(arr, dtype=dtype, copy=copy)
  File "C:\Users\alejo\AppData\Local\Packages\PythonSoftwareFoundation.Python.3.10_qbz5n2kfra8p0\LocalCache\local-packages\Python310\site-packages\pandas\core\arrays\masked.py", line 132, in _from_sequence
    values, mask = cls._coerce_to_array(scalars, dtype=dtype, copy=copy)
  File "C:\Users\alejo\AppData\Local\Packages\PythonSoftwareFoundation.Python.3.10_qbz5n2kfra8p0\LocalCache\local-packages\Python310\site-packages\pandas\core\arrays\boolean.py", line 344, in _coerce_to_array
    return coerce_to_array(value, copy=copy)
  File "C:\Users\alejo\AppData\Local\Packages\PythonSoftwareFoundation.Python.3.10_qbz5n2kfra8p0\LocalCache\local-packages\Python310\site-packages\pandas\core\arrays\boolean.py", line 194, in coerce_to_array
    raise TypeError("Need to pass bool-like values")
TypeError: Need to pass bool-like values
2023-05-18 23:45:33,882 - ERROR - Se ha presentado una excepcion: Need to pass bool-like values
Traceback (most recent call last):
  File "C:\Users\alejo\AppData\Local\Temp\ipykernel_8984\4051536291.py", line 17, in <module>
    df['DIVERTED']=df['DIVERTED'].astype('boolean')
  File "C:\Users\alejo\AppData\Local\Packages\PythonSoftwareFoundation.Python.3.10_qbz5n2kfra8p0\LocalCache\local-packages\Python310\site-packages\pandas\core\generic.py", line 6240, in astype
    new_data = self._mgr.astype(dtype=dtype, copy=copy, errors=errors)
  File "C:\Users\alejo\AppData\Local\Packages\PythonSoftwareFoundation.Python.3.10_qbz5n2kfra8p0\LocalCache\local-packages\Python310\site-packages\pandas\core\internals\managers.py", line 448, in astype
    return self.apply("astype", dtype=dtype, copy=copy, errors=errors)
  File "C:\Users\alejo\AppData\Local\Packages\PythonSoftwareFoundation.Python.3.10_qbz5n2kfra8p0\LocalCache\local-packages\Python310\site-packages\pandas\core\internals\managers.py", line 352, in apply
    applied = getattr(b, f)(**kwargs)
  File "C:\Users\alejo\AppData\Local\Packages\PythonSoftwareFoundation.Python.3.10_qbz5n2kfra8p0\LocalCache\local-packages\Python310\site-packages\pandas\core\internals\blocks.py", line 526, in astype
    new_values = astype_array_safe(values, dtype, copy=copy, errors=errors)
  File "C:\Users\alejo\AppData\Local\Packages\PythonSoftwareFoundation.Python.3.10_qbz5n2kfra8p0\LocalCache\local-packages\Python310\site-packages\pandas\core\dtypes\astype.py", line 299, in astype_array_safe
    new_values = astype_array(values, dtype, copy=copy)
  File "C:\Users\alejo\AppData\Local\Packages\PythonSoftwareFoundation.Python.3.10_qbz5n2kfra8p0\LocalCache\local-packages\Python310\site-packages\pandas\core\dtypes\astype.py", line 230, in astype_array
    values = astype_nansafe(values, dtype, copy=copy)
  File "C:\Users\alejo\AppData\Local\Packages\PythonSoftwareFoundation.Python.3.10_qbz5n2kfra8p0\LocalCache\local-packages\Python310\site-packages\pandas\core\dtypes\astype.py", line 95, in astype_nansafe
    return dtype.construct_array_type()._from_sequence(arr, dtype=dtype, copy=copy)
  File "C:\Users\alejo\AppData\Local\Packages\PythonSoftwareFoundation.Python.3.10_qbz5n2kfra8p0\LocalCache\local-packages\Python310\site-packages\pandas\core\arrays\masked.py", line 132, in _from_sequence
    values, mask = cls._coerce_to_array(scalars, dtype=dtype, copy=copy)
  File "C:\Users\alejo\AppData\Local\Packages\PythonSoftwareFoundation.Python.3.10_qbz5n2kfra8p0\LocalCache\local-packages\Python310\site-packages\pandas\core\arrays\boolean.py", line 344, in _coerce_to_array
    return coerce_to_array(value, copy=copy)
  File "C:\Users\alejo\AppData\Local\Packages\PythonSoftwareFoundation.Python.3.10_qbz5n2kfra8p0\LocalCache\local-packages\Python310\site-packages\pandas\core\arrays\boolean.py", line 194, in coerce_to_array
    raise TypeError("Need to pass bool-like values")
TypeError: Need to pass bool-like values
2023-05-18 23:45:33,882 - ERROR - Se ha presentado una excepcion: Need to pass bool-like values
Traceback (most recent call last):
  File "C:\Users\alejo\AppData\Local\Temp\ipykernel_8984\4051536291.py", line 17, in <module>
    df['DIVERTED']=df['DIVERTED'].astype('boolean')
  File "C:\Users\alejo\AppData\Local\Packages\PythonSoftwareFoundation.Python.3.10_qbz5n2kfra8p0\LocalCache\local-packages\Python310\site-packages\pandas\core\generic.py", line 6240, in astype
    new_data = self._mgr.astype(dtype=dtype, copy=copy, errors=errors)
  File "C:\Users\alejo\AppData\Local\Packages\PythonSoftwareFoundation.Python.3.10_qbz5n2kfra8p0\LocalCache\local-packages\Python310\site-packages\pandas\core\internals\managers.py", line 448, in astype
    return self.apply("astype", dtype=dtype, copy=copy, errors=errors)
  File "C:\Users\alejo\AppData\Local\Packages\PythonSoftwareFoundation.Python.3.10_qbz5n2kfra8p0\LocalCache\local-packages\Python310\site-packages\pandas\core\internals\managers.py", line 352, in apply
    applied = getattr(b, f)(**kwargs)
  File "C:\Users\alejo\AppData\Local\Packages\PythonSoftwareFoundation.Python.3.10_qbz5n2kfra8p0\LocalCache\local-packages\Python310\site-packages\pandas\core\internals\blocks.py", line 526, in astype
    new_values = astype_array_safe(values, dtype, copy=copy, errors=errors)
  File "C:\Users\alejo\AppData\Local\Packages\PythonSoftwareFoundation.Python.3.10_qbz5n2kfra8p0\LocalCache\local-packages\Python310\site-packages\pandas\core\dtypes\astype.py", line 299, in astype_array_safe
    new_values = astype_array(values, dtype, copy=copy)
  File "C:\Users\alejo\AppData\Local\Packages\PythonSoftwareFoundation.Python.3.10_qbz5n2kfra8p0\LocalCache\local-packages\Python310\site-packages\pandas\core\dtypes\astype.py", line 230, in astype_array
    values = astype_nansafe(values, dtype, copy=copy)
  File "C:\Users\alejo\AppData\Local\Packages\PythonSoftwareFoundation.Python.3.10_qbz5n2kfra8p0\LocalCache\local-packages\Python310\site-packages\pandas\core\dtypes\astype.py", line 95, in astype_nansafe
    return dtype.construct_array_type()._from_sequence(arr, dtype=dtype, copy=copy)
  File "C:\Users\alejo\AppData\Local\Packages\PythonSoftwareFoundation.Python.3.10_qbz5n2kfra8p0\LocalCache\local-packages\Python310\site-packages\pandas\core\arrays\masked.py", line 132, in _from_sequence
    values, mask = cls._coerce_to_array(scalars, dtype=dtype, copy=copy)
  File "C:\Users\alejo\AppData\Local\Packages\PythonSoftwareFoundation.Python.3.10_qbz5n2kfra8p0\LocalCache\local-packages\Python310\site-packages\pandas\core\arrays\boolean.py", line 344, in _coerce_to_array
    return coerce_to_array(value, copy=copy)
  File "C:\Users\alejo\AppData\Local\Packages\PythonSoftwareFoundation.Python.3.10_qbz5n2kfra8p0\LocalCache\local-packages\Python310\site-packages\pandas\core\arrays\boolean.py", line 194, in coerce_to_array
    raise TypeError("Need to pass bool-like values")
TypeError: Need to pass bool-like values
2023-05-19 01:24:01,319 - ERROR - Se ha presentado una excepcion: time data '0' does not match format '%H%M' (match)
Traceback (most recent call last):
  File "C:\Users\alejo\AppData\Local\Temp\ipykernel_18724\3120231763.py", line 17, in <module>
    df[columna] = pd.to_datetime(df[columna], format='%H%M').dt.time
  File "C:\Users\alejo\AppData\Local\Packages\PythonSoftwareFoundation.Python.3.10_qbz5n2kfra8p0\LocalCache\local-packages\Python310\site-packages\pandas\core\tools\datetimes.py", line 1064, in to_datetime
    cache_array = _maybe_cache(arg, format, cache, convert_listlike)
  File "C:\Users\alejo\AppData\Local\Packages\PythonSoftwareFoundation.Python.3.10_qbz5n2kfra8p0\LocalCache\local-packages\Python310\site-packages\pandas\core\tools\datetimes.py", line 229, in _maybe_cache
    cache_dates = convert_listlike(unique_dates, format)
  File "C:\Users\alejo\AppData\Local\Packages\PythonSoftwareFoundation.Python.3.10_qbz5n2kfra8p0\LocalCache\local-packages\Python310\site-packages\pandas\core\tools\datetimes.py", line 430, in _convert_listlike_datetimes
    res = _to_datetime_with_format(
  File "C:\Users\alejo\AppData\Local\Packages\PythonSoftwareFoundation.Python.3.10_qbz5n2kfra8p0\LocalCache\local-packages\Python310\site-packages\pandas\core\tools\datetimes.py", line 538, in _to_datetime_with_format
    res = _array_strptime_with_fallback(
  File "C:\Users\alejo\AppData\Local\Packages\PythonSoftwareFoundation.Python.3.10_qbz5n2kfra8p0\LocalCache\local-packages\Python310\site-packages\pandas\core\tools\datetimes.py", line 473, in _array_strptime_with_fallback
    result, timezones = array_strptime(arg, fmt, exact=exact, errors=errors)
  File "pandas\_libs\tslibs\strptime.pyx", line 150, in pandas._libs.tslibs.strptime.array_strptime
ValueError: time data '0' does not match format '%H%M' (match)
2023-05-19 01:24:01,319 - ERROR - Se ha presentado una excepcion: time data '0' does not match format '%H%M' (match)
Traceback (most recent call last):
  File "C:\Users\alejo\AppData\Local\Temp\ipykernel_18724\3120231763.py", line 17, in <module>
    df[columna] = pd.to_datetime(df[columna], format='%H%M').dt.time
  File "C:\Users\alejo\AppData\Local\Packages\PythonSoftwareFoundation.Python.3.10_qbz5n2kfra8p0\LocalCache\local-packages\Python310\site-packages\pandas\core\tools\datetimes.py", line 1064, in to_datetime
    cache_array = _maybe_cache(arg, format, cache, convert_listlike)
  File "C:\Users\alejo\AppData\Local\Packages\PythonSoftwareFoundation.Python.3.10_qbz5n2kfra8p0\LocalCache\local-packages\Python310\site-packages\pandas\core\tools\datetimes.py", line 229, in _maybe_cache
    cache_dates = convert_listlike(unique_dates, format)
  File "C:\Users\alejo\AppData\Local\Packages\PythonSoftwareFoundation.Python.3.10_qbz5n2kfra8p0\LocalCache\local-packages\Python310\site-packages\pandas\core\tools\datetimes.py", line 430, in _convert_listlike_datetimes
    res = _to_datetime_with_format(
  File "C:\Users\alejo\AppData\Local\Packages\PythonSoftwareFoundation.Python.3.10_qbz5n2kfra8p0\LocalCache\local-packages\Python310\site-packages\pandas\core\tools\datetimes.py", line 538, in _to_datetime_with_format
    res = _array_strptime_with_fallback(
  File "C:\Users\alejo\AppData\Local\Packages\PythonSoftwareFoundation.Python.3.10_qbz5n2kfra8p0\LocalCache\local-packages\Python310\site-packages\pandas\core\tools\datetimes.py", line 473, in _array_strptime_with_fallback
    result, timezones = array_strptime(arg, fmt, exact=exact, errors=errors)
  File "pandas\_libs\tslibs\strptime.pyx", line 150, in pandas._libs.tslibs.strptime.array_strptime
ValueError: time data '0' does not match format '%H%M' (match)
2023-05-19 01:24:01,319 - ERROR - Se ha presentado una excepcion: time data '0' does not match format '%H%M' (match)
Traceback (most recent call last):
  File "C:\Users\alejo\AppData\Local\Temp\ipykernel_18724\3120231763.py", line 17, in <module>
    df[columna] = pd.to_datetime(df[columna], format='%H%M').dt.time
  File "C:\Users\alejo\AppData\Local\Packages\PythonSoftwareFoundation.Python.3.10_qbz5n2kfra8p0\LocalCache\local-packages\Python310\site-packages\pandas\core\tools\datetimes.py", line 1064, in to_datetime
    cache_array = _maybe_cache(arg, format, cache, convert_listlike)
  File "C:\Users\alejo\AppData\Local\Packages\PythonSoftwareFoundation.Python.3.10_qbz5n2kfra8p0\LocalCache\local-packages\Python310\site-packages\pandas\core\tools\datetimes.py", line 229, in _maybe_cache
    cache_dates = convert_listlike(unique_dates, format)
  File "C:\Users\alejo\AppData\Local\Packages\PythonSoftwareFoundation.Python.3.10_qbz5n2kfra8p0\LocalCache\local-packages\Python310\site-packages\pandas\core\tools\datetimes.py", line 430, in _convert_listlike_datetimes
    res = _to_datetime_with_format(
  File "C:\Users\alejo\AppData\Local\Packages\PythonSoftwareFoundation.Python.3.10_qbz5n2kfra8p0\LocalCache\local-packages\Python310\site-packages\pandas\core\tools\datetimes.py", line 538, in _to_datetime_with_format
    res = _array_strptime_with_fallback(
  File "C:\Users\alejo\AppData\Local\Packages\PythonSoftwareFoundation.Python.3.10_qbz5n2kfra8p0\LocalCache\local-packages\Python310\site-packages\pandas\core\tools\datetimes.py", line 473, in _array_strptime_with_fallback
    result, timezones = array_strptime(arg, fmt, exact=exact, errors=errors)
  File "pandas\_libs\tslibs\strptime.pyx", line 150, in pandas._libs.tslibs.strptime.array_strptime
ValueError: time data '0' does not match format '%H%M' (match)
2023-05-20 00:06:00,725 - ERROR - Se ha presentado una excepcion: Can only use .str accessor with string values!
Traceback (most recent call last):
  File "C:\Users\alejo\AppData\Local\Temp\ipykernel_25844\741988053.py", line 6, in <module>
    df['DISTANCE']=df['DISTANCE'].str.replace(' miles', '')
  File "C:\Users\alejo\AppData\Local\Packages\PythonSoftwareFoundation.Python.3.10_qbz5n2kfra8p0\LocalCache\local-packages\Python310\site-packages\pandas\core\generic.py", line 5902, in __getattr__
    return object.__getattribute__(self, name)
  File "C:\Users\alejo\AppData\Local\Packages\PythonSoftwareFoundation.Python.3.10_qbz5n2kfra8p0\LocalCache\local-packages\Python310\site-packages\pandas\core\accessor.py", line 182, in __get__
    accessor_obj = self._accessor(obj)
  File "C:\Users\alejo\AppData\Local\Packages\PythonSoftwareFoundation.Python.3.10_qbz5n2kfra8p0\LocalCache\local-packages\Python310\site-packages\pandas\core\strings\accessor.py", line 181, in __init__
    self._inferred_dtype = self._validate(data)
  File "C:\Users\alejo\AppData\Local\Packages\PythonSoftwareFoundation.Python.3.10_qbz5n2kfra8p0\LocalCache\local-packages\Python310\site-packages\pandas\core\strings\accessor.py", line 235, in _validate
    raise AttributeError("Can only use .str accessor with string values!")
AttributeError: Can only use .str accessor with string values!
2023-05-20 00:06:00,725 - ERROR - Se ha presentado una excepcion: Can only use .str accessor with string values!
Traceback (most recent call last):
  File "C:\Users\alejo\AppData\Local\Temp\ipykernel_25844\741988053.py", line 6, in <module>
    df['DISTANCE']=df['DISTANCE'].str.replace(' miles', '')
  File "C:\Users\alejo\AppData\Local\Packages\PythonSoftwareFoundation.Python.3.10_qbz5n2kfra8p0\LocalCache\local-packages\Python310\site-packages\pandas\core\generic.py", line 5902, in __getattr__
    return object.__getattribute__(self, name)
  File "C:\Users\alejo\AppData\Local\Packages\PythonSoftwareFoundation.Python.3.10_qbz5n2kfra8p0\LocalCache\local-packages\Python310\site-packages\pandas\core\accessor.py", line 182, in __get__
    accessor_obj = self._accessor(obj)
  File "C:\Users\alejo\AppData\Local\Packages\PythonSoftwareFoundation.Python.3.10_qbz5n2kfra8p0\LocalCache\local-packages\Python310\site-packages\pandas\core\strings\accessor.py", line 181, in __init__
    self._inferred_dtype = self._validate(data)
  File "C:\Users\alejo\AppData\Local\Packages\PythonSoftwareFoundation.Python.3.10_qbz5n2kfra8p0\LocalCache\local-packages\Python310\site-packages\pandas\core\strings\accessor.py", line 235, in _validate
    raise AttributeError("Can only use .str accessor with string values!")
AttributeError: Can only use .str accessor with string values!
2023-05-20 00:06:22,862 - ERROR - Se ha presentado una excepcion: time data '1997-01-020' does not match format '%Y-%m-%d%H%M' (match)
Traceback (most recent call last):
  File "C:\Users\alejo\AppData\Local\Temp\ipykernel_25844\741988053.py", line 17, in <module>
    pd.to_datetime(df['FLIGHTDATE'].dt.strftime('%Y-%m-%d') + df[columna].astype(str), format='%Y-%m-%d%H%M')
  File "C:\Users\alejo\AppData\Local\Packages\PythonSoftwareFoundation.Python.3.10_qbz5n2kfra8p0\LocalCache\local-packages\Python310\site-packages\pandas\core\tools\datetimes.py", line 1068, in to_datetime
    values = convert_listlike(arg._values, format)
  File "C:\Users\alejo\AppData\Local\Packages\PythonSoftwareFoundation.Python.3.10_qbz5n2kfra8p0\LocalCache\local-packages\Python310\site-packages\pandas\core\tools\datetimes.py", line 430, in _convert_listlike_datetimes
    res = _to_datetime_with_format(
  File "C:\Users\alejo\AppData\Local\Packages\PythonSoftwareFoundation.Python.3.10_qbz5n2kfra8p0\LocalCache\local-packages\Python310\site-packages\pandas\core\tools\datetimes.py", line 538, in _to_datetime_with_format
    res = _array_strptime_with_fallback(
  File "C:\Users\alejo\AppData\Local\Packages\PythonSoftwareFoundation.Python.3.10_qbz5n2kfra8p0\LocalCache\local-packages\Python310\site-packages\pandas\core\tools\datetimes.py", line 473, in _array_strptime_with_fallback
    result, timezones = array_strptime(arg, fmt, exact=exact, errors=errors)
  File "pandas\_libs\tslibs\strptime.pyx", line 150, in pandas._libs.tslibs.strptime.array_strptime
ValueError: time data '1997-01-020' does not match format '%Y-%m-%d%H%M' (match)
2023-05-20 00:06:22,862 - ERROR - Se ha presentado una excepcion: time data '1997-01-020' does not match format '%Y-%m-%d%H%M' (match)
Traceback (most recent call last):
  File "C:\Users\alejo\AppData\Local\Temp\ipykernel_25844\741988053.py", line 17, in <module>
    pd.to_datetime(df['FLIGHTDATE'].dt.strftime('%Y-%m-%d') + df[columna].astype(str), format='%Y-%m-%d%H%M')
  File "C:\Users\alejo\AppData\Local\Packages\PythonSoftwareFoundation.Python.3.10_qbz5n2kfra8p0\LocalCache\local-packages\Python310\site-packages\pandas\core\tools\datetimes.py", line 1068, in to_datetime
    values = convert_listlike(arg._values, format)
  File "C:\Users\alejo\AppData\Local\Packages\PythonSoftwareFoundation.Python.3.10_qbz5n2kfra8p0\LocalCache\local-packages\Python310\site-packages\pandas\core\tools\datetimes.py", line 430, in _convert_listlike_datetimes
    res = _to_datetime_with_format(
  File "C:\Users\alejo\AppData\Local\Packages\PythonSoftwareFoundation.Python.3.10_qbz5n2kfra8p0\LocalCache\local-packages\Python310\site-packages\pandas\core\tools\datetimes.py", line 538, in _to_datetime_with_format
    res = _array_strptime_with_fallback(
  File "C:\Users\alejo\AppData\Local\Packages\PythonSoftwareFoundation.Python.3.10_qbz5n2kfra8p0\LocalCache\local-packages\Python310\site-packages\pandas\core\tools\datetimes.py", line 473, in _array_strptime_with_fallback
    result, timezones = array_strptime(arg, fmt, exact=exact, errors=errors)
  File "pandas\_libs\tslibs\strptime.pyx", line 150, in pandas._libs.tslibs.strptime.array_strptime
ValueError: time data '1997-01-020' does not match format '%Y-%m-%d%H%M' (match)
2023-05-20 00:06:22,862 - ERROR - Se ha presentado una excepcion: time data '1997-01-020' does not match format '%Y-%m-%d%H%M' (match)
Traceback (most recent call last):
  File "C:\Users\alejo\AppData\Local\Temp\ipykernel_25844\741988053.py", line 17, in <module>
    pd.to_datetime(df['FLIGHTDATE'].dt.strftime('%Y-%m-%d') + df[columna].astype(str), format='%Y-%m-%d%H%M')
  File "C:\Users\alejo\AppData\Local\Packages\PythonSoftwareFoundation.Python.3.10_qbz5n2kfra8p0\LocalCache\local-packages\Python310\site-packages\pandas\core\tools\datetimes.py", line 1068, in to_datetime
    values = convert_listlike(arg._values, format)
  File "C:\Users\alejo\AppData\Local\Packages\PythonSoftwareFoundation.Python.3.10_qbz5n2kfra8p0\LocalCache\local-packages\Python310\site-packages\pandas\core\tools\datetimes.py", line 430, in _convert_listlike_datetimes
    res = _to_datetime_with_format(
  File "C:\Users\alejo\AppData\Local\Packages\PythonSoftwareFoundation.Python.3.10_qbz5n2kfra8p0\LocalCache\local-packages\Python310\site-packages\pandas\core\tools\datetimes.py", line 538, in _to_datetime_with_format
    res = _array_strptime_with_fallback(
  File "C:\Users\alejo\AppData\Local\Packages\PythonSoftwareFoundation.Python.3.10_qbz5n2kfra8p0\LocalCache\local-packages\Python310\site-packages\pandas\core\tools\datetimes.py", line 473, in _array_strptime_with_fallback
    result, timezones = array_strptime(arg, fmt, exact=exact, errors=errors)
  File "pandas\_libs\tslibs\strptime.pyx", line 150, in pandas._libs.tslibs.strptime.array_strptime
ValueError: time data '1997-01-020' does not match format '%Y-%m-%d%H%M' (match)
2023-05-20 00:10:04,943 - ERROR - Se ha presentado una excepcion: Can only use .str accessor with string values!
Traceback (most recent call last):
  File "C:\Users\alejo\AppData\Local\Temp\ipykernel_25844\513103247.py", line 6, in <module>
    df['DISTANCE']=df['DISTANCE'].str.replace(' miles', '')
  File "C:\Users\alejo\AppData\Local\Packages\PythonSoftwareFoundation.Python.3.10_qbz5n2kfra8p0\LocalCache\local-packages\Python310\site-packages\pandas\core\generic.py", line 5902, in __getattr__
    return object.__getattribute__(self, name)
  File "C:\Users\alejo\AppData\Local\Packages\PythonSoftwareFoundation.Python.3.10_qbz5n2kfra8p0\LocalCache\local-packages\Python310\site-packages\pandas\core\accessor.py", line 182, in __get__
    accessor_obj = self._accessor(obj)
  File "C:\Users\alejo\AppData\Local\Packages\PythonSoftwareFoundation.Python.3.10_qbz5n2kfra8p0\LocalCache\local-packages\Python310\site-packages\pandas\core\strings\accessor.py", line 181, in __init__
    self._inferred_dtype = self._validate(data)
  File "C:\Users\alejo\AppData\Local\Packages\PythonSoftwareFoundation.Python.3.10_qbz5n2kfra8p0\LocalCache\local-packages\Python310\site-packages\pandas\core\strings\accessor.py", line 235, in _validate
    raise AttributeError("Can only use .str accessor with string values!")
AttributeError: Can only use .str accessor with string values!
2023-05-20 00:10:04,943 - ERROR - Se ha presentado una excepcion: Can only use .str accessor with string values!
Traceback (most recent call last):
  File "C:\Users\alejo\AppData\Local\Temp\ipykernel_25844\513103247.py", line 6, in <module>
    df['DISTANCE']=df['DISTANCE'].str.replace(' miles', '')
  File "C:\Users\alejo\AppData\Local\Packages\PythonSoftwareFoundation.Python.3.10_qbz5n2kfra8p0\LocalCache\local-packages\Python310\site-packages\pandas\core\generic.py", line 5902, in __getattr__
    return object.__getattribute__(self, name)
  File "C:\Users\alejo\AppData\Local\Packages\PythonSoftwareFoundation.Python.3.10_qbz5n2kfra8p0\LocalCache\local-packages\Python310\site-packages\pandas\core\accessor.py", line 182, in __get__
    accessor_obj = self._accessor(obj)
  File "C:\Users\alejo\AppData\Local\Packages\PythonSoftwareFoundation.Python.3.10_qbz5n2kfra8p0\LocalCache\local-packages\Python310\site-packages\pandas\core\strings\accessor.py", line 181, in __init__
    self._inferred_dtype = self._validate(data)
  File "C:\Users\alejo\AppData\Local\Packages\PythonSoftwareFoundation.Python.3.10_qbz5n2kfra8p0\LocalCache\local-packages\Python310\site-packages\pandas\core\strings\accessor.py", line 235, in _validate
    raise AttributeError("Can only use .str accessor with string values!")
AttributeError: Can only use .str accessor with string values!
2023-05-20 00:10:04,943 - ERROR - Se ha presentado una excepcion: Can only use .str accessor with string values!
Traceback (most recent call last):
  File "C:\Users\alejo\AppData\Local\Temp\ipykernel_25844\513103247.py", line 6, in <module>
    df['DISTANCE']=df['DISTANCE'].str.replace(' miles', '')
  File "C:\Users\alejo\AppData\Local\Packages\PythonSoftwareFoundation.Python.3.10_qbz5n2kfra8p0\LocalCache\local-packages\Python310\site-packages\pandas\core\generic.py", line 5902, in __getattr__
    return object.__getattribute__(self, name)
  File "C:\Users\alejo\AppData\Local\Packages\PythonSoftwareFoundation.Python.3.10_qbz5n2kfra8p0\LocalCache\local-packages\Python310\site-packages\pandas\core\accessor.py", line 182, in __get__
    accessor_obj = self._accessor(obj)
  File "C:\Users\alejo\AppData\Local\Packages\PythonSoftwareFoundation.Python.3.10_qbz5n2kfra8p0\LocalCache\local-packages\Python310\site-packages\pandas\core\strings\accessor.py", line 181, in __init__
    self._inferred_dtype = self._validate(data)
  File "C:\Users\alejo\AppData\Local\Packages\PythonSoftwareFoundation.Python.3.10_qbz5n2kfra8p0\LocalCache\local-packages\Python310\site-packages\pandas\core\strings\accessor.py", line 235, in _validate
    raise AttributeError("Can only use .str accessor with string values!")
AttributeError: Can only use .str accessor with string values!
2023-05-20 00:10:18,083 - ERROR - Se ha presentado una excepcion: Can only use .dt accessor with datetimelike values
Traceback (most recent call last):
  File "C:\Users\alejo\AppData\Local\Temp\ipykernel_25844\513103247.py", line 17, in <module>
    df[columna]=df['FLIGHTDATE'] + df[columna].dt.strftime('%H%M')
  File "C:\Users\alejo\AppData\Local\Packages\PythonSoftwareFoundation.Python.3.10_qbz5n2kfra8p0\LocalCache\local-packages\Python310\site-packages\pandas\core\generic.py", line 5902, in __getattr__
    return object.__getattribute__(self, name)
  File "C:\Users\alejo\AppData\Local\Packages\PythonSoftwareFoundation.Python.3.10_qbz5n2kfra8p0\LocalCache\local-packages\Python310\site-packages\pandas\core\accessor.py", line 182, in __get__
    accessor_obj = self._accessor(obj)
  File "C:\Users\alejo\AppData\Local\Packages\PythonSoftwareFoundation.Python.3.10_qbz5n2kfra8p0\LocalCache\local-packages\Python310\site-packages\pandas\core\indexes\accessors.py", line 512, in __new__
    raise AttributeError("Can only use .dt accessor with datetimelike values")
AttributeError: Can only use .dt accessor with datetimelike values
2023-05-20 00:10:18,083 - ERROR - Se ha presentado una excepcion: Can only use .dt accessor with datetimelike values
Traceback (most recent call last):
  File "C:\Users\alejo\AppData\Local\Temp\ipykernel_25844\513103247.py", line 17, in <module>
    df[columna]=df['FLIGHTDATE'] + df[columna].dt.strftime('%H%M')
  File "C:\Users\alejo\AppData\Local\Packages\PythonSoftwareFoundation.Python.3.10_qbz5n2kfra8p0\LocalCache\local-packages\Python310\site-packages\pandas\core\generic.py", line 5902, in __getattr__
    return object.__getattribute__(self, name)
  File "C:\Users\alejo\AppData\Local\Packages\PythonSoftwareFoundation.Python.3.10_qbz5n2kfra8p0\LocalCache\local-packages\Python310\site-packages\pandas\core\accessor.py", line 182, in __get__
    accessor_obj = self._accessor(obj)
  File "C:\Users\alejo\AppData\Local\Packages\PythonSoftwareFoundation.Python.3.10_qbz5n2kfra8p0\LocalCache\local-packages\Python310\site-packages\pandas\core\indexes\accessors.py", line 512, in __new__
    raise AttributeError("Can only use .dt accessor with datetimelike values")
AttributeError: Can only use .dt accessor with datetimelike values
2023-05-20 00:10:18,083 - ERROR - Se ha presentado una excepcion: Can only use .dt accessor with datetimelike values
Traceback (most recent call last):
  File "C:\Users\alejo\AppData\Local\Temp\ipykernel_25844\513103247.py", line 17, in <module>
    df[columna]=df['FLIGHTDATE'] + df[columna].dt.strftime('%H%M')
  File "C:\Users\alejo\AppData\Local\Packages\PythonSoftwareFoundation.Python.3.10_qbz5n2kfra8p0\LocalCache\local-packages\Python310\site-packages\pandas\core\generic.py", line 5902, in __getattr__
    return object.__getattribute__(self, name)
  File "C:\Users\alejo\AppData\Local\Packages\PythonSoftwareFoundation.Python.3.10_qbz5n2kfra8p0\LocalCache\local-packages\Python310\site-packages\pandas\core\accessor.py", line 182, in __get__
    accessor_obj = self._accessor(obj)
  File "C:\Users\alejo\AppData\Local\Packages\PythonSoftwareFoundation.Python.3.10_qbz5n2kfra8p0\LocalCache\local-packages\Python310\site-packages\pandas\core\indexes\accessors.py", line 512, in __new__
    raise AttributeError("Can only use .dt accessor with datetimelike values")
AttributeError: Can only use .dt accessor with datetimelike values
2023-05-20 00:10:18,083 - ERROR - Se ha presentado una excepcion: Can only use .dt accessor with datetimelike values
Traceback (most recent call last):
  File "C:\Users\alejo\AppData\Local\Temp\ipykernel_25844\513103247.py", line 17, in <module>
    df[columna]=df['FLIGHTDATE'] + df[columna].dt.strftime('%H%M')
  File "C:\Users\alejo\AppData\Local\Packages\PythonSoftwareFoundation.Python.3.10_qbz5n2kfra8p0\LocalCache\local-packages\Python310\site-packages\pandas\core\generic.py", line 5902, in __getattr__
    return object.__getattribute__(self, name)
  File "C:\Users\alejo\AppData\Local\Packages\PythonSoftwareFoundation.Python.3.10_qbz5n2kfra8p0\LocalCache\local-packages\Python310\site-packages\pandas\core\accessor.py", line 182, in __get__
    accessor_obj = self._accessor(obj)
  File "C:\Users\alejo\AppData\Local\Packages\PythonSoftwareFoundation.Python.3.10_qbz5n2kfra8p0\LocalCache\local-packages\Python310\site-packages\pandas\core\indexes\accessors.py", line 512, in __new__
    raise AttributeError("Can only use .dt accessor with datetimelike values")
AttributeError: Can only use .dt accessor with datetimelike values
2023-05-20 00:11:28,332 - ERROR - Se ha presentado una excepcion: Can only use .str accessor with string values!
Traceback (most recent call last):
  File "C:\Users\alejo\AppData\Local\Temp\ipykernel_25844\2706685986.py", line 6, in <module>
    df['DISTANCE']=df['DISTANCE'].str.replace(' miles', '')
  File "C:\Users\alejo\AppData\Local\Packages\PythonSoftwareFoundation.Python.3.10_qbz5n2kfra8p0\LocalCache\local-packages\Python310\site-packages\pandas\core\generic.py", line 5902, in __getattr__
    return object.__getattribute__(self, name)
  File "C:\Users\alejo\AppData\Local\Packages\PythonSoftwareFoundation.Python.3.10_qbz5n2kfra8p0\LocalCache\local-packages\Python310\site-packages\pandas\core\accessor.py", line 182, in __get__
    accessor_obj = self._accessor(obj)
  File "C:\Users\alejo\AppData\Local\Packages\PythonSoftwareFoundation.Python.3.10_qbz5n2kfra8p0\LocalCache\local-packages\Python310\site-packages\pandas\core\strings\accessor.py", line 181, in __init__
    self._inferred_dtype = self._validate(data)
  File "C:\Users\alejo\AppData\Local\Packages\PythonSoftwareFoundation.Python.3.10_qbz5n2kfra8p0\LocalCache\local-packages\Python310\site-packages\pandas\core\strings\accessor.py", line 235, in _validate
    raise AttributeError("Can only use .str accessor with string values!")
AttributeError: Can only use .str accessor with string values!
2023-05-20 00:11:28,332 - ERROR - Se ha presentado una excepcion: Can only use .str accessor with string values!
Traceback (most recent call last):
  File "C:\Users\alejo\AppData\Local\Temp\ipykernel_25844\2706685986.py", line 6, in <module>
    df['DISTANCE']=df['DISTANCE'].str.replace(' miles', '')
  File "C:\Users\alejo\AppData\Local\Packages\PythonSoftwareFoundation.Python.3.10_qbz5n2kfra8p0\LocalCache\local-packages\Python310\site-packages\pandas\core\generic.py", line 5902, in __getattr__
    return object.__getattribute__(self, name)
  File "C:\Users\alejo\AppData\Local\Packages\PythonSoftwareFoundation.Python.3.10_qbz5n2kfra8p0\LocalCache\local-packages\Python310\site-packages\pandas\core\accessor.py", line 182, in __get__
    accessor_obj = self._accessor(obj)
  File "C:\Users\alejo\AppData\Local\Packages\PythonSoftwareFoundation.Python.3.10_qbz5n2kfra8p0\LocalCache\local-packages\Python310\site-packages\pandas\core\strings\accessor.py", line 181, in __init__
    self._inferred_dtype = self._validate(data)
  File "C:\Users\alejo\AppData\Local\Packages\PythonSoftwareFoundation.Python.3.10_qbz5n2kfra8p0\LocalCache\local-packages\Python310\site-packages\pandas\core\strings\accessor.py", line 235, in _validate
    raise AttributeError("Can only use .str accessor with string values!")
AttributeError: Can only use .str accessor with string values!
2023-05-20 00:11:28,332 - ERROR - Se ha presentado una excepcion: Can only use .str accessor with string values!
Traceback (most recent call last):
  File "C:\Users\alejo\AppData\Local\Temp\ipykernel_25844\2706685986.py", line 6, in <module>
    df['DISTANCE']=df['DISTANCE'].str.replace(' miles', '')
  File "C:\Users\alejo\AppData\Local\Packages\PythonSoftwareFoundation.Python.3.10_qbz5n2kfra8p0\LocalCache\local-packages\Python310\site-packages\pandas\core\generic.py", line 5902, in __getattr__
    return object.__getattribute__(self, name)
  File "C:\Users\alejo\AppData\Local\Packages\PythonSoftwareFoundation.Python.3.10_qbz5n2kfra8p0\LocalCache\local-packages\Python310\site-packages\pandas\core\accessor.py", line 182, in __get__
    accessor_obj = self._accessor(obj)
  File "C:\Users\alejo\AppData\Local\Packages\PythonSoftwareFoundation.Python.3.10_qbz5n2kfra8p0\LocalCache\local-packages\Python310\site-packages\pandas\core\strings\accessor.py", line 181, in __init__
    self._inferred_dtype = self._validate(data)
  File "C:\Users\alejo\AppData\Local\Packages\PythonSoftwareFoundation.Python.3.10_qbz5n2kfra8p0\LocalCache\local-packages\Python310\site-packages\pandas\core\strings\accessor.py", line 235, in _validate
    raise AttributeError("Can only use .str accessor with string values!")
AttributeError: Can only use .str accessor with string values!
2023-05-20 00:11:28,332 - ERROR - Se ha presentado una excepcion: Can only use .str accessor with string values!
Traceback (most recent call last):
  File "C:\Users\alejo\AppData\Local\Temp\ipykernel_25844\2706685986.py", line 6, in <module>
    df['DISTANCE']=df['DISTANCE'].str.replace(' miles', '')
  File "C:\Users\alejo\AppData\Local\Packages\PythonSoftwareFoundation.Python.3.10_qbz5n2kfra8p0\LocalCache\local-packages\Python310\site-packages\pandas\core\generic.py", line 5902, in __getattr__
    return object.__getattribute__(self, name)
  File "C:\Users\alejo\AppData\Local\Packages\PythonSoftwareFoundation.Python.3.10_qbz5n2kfra8p0\LocalCache\local-packages\Python310\site-packages\pandas\core\accessor.py", line 182, in __get__
    accessor_obj = self._accessor(obj)
  File "C:\Users\alejo\AppData\Local\Packages\PythonSoftwareFoundation.Python.3.10_qbz5n2kfra8p0\LocalCache\local-packages\Python310\site-packages\pandas\core\strings\accessor.py", line 181, in __init__
    self._inferred_dtype = self._validate(data)
  File "C:\Users\alejo\AppData\Local\Packages\PythonSoftwareFoundation.Python.3.10_qbz5n2kfra8p0\LocalCache\local-packages\Python310\site-packages\pandas\core\strings\accessor.py", line 235, in _validate
    raise AttributeError("Can only use .str accessor with string values!")
AttributeError: Can only use .str accessor with string values!
2023-05-20 00:11:39,753 - ERROR - Se ha presentado una excepcion: time data '0' does not match format '%H%M' (match)
Traceback (most recent call last):
  File "C:\Users\alejo\AppData\Local\Temp\ipykernel_25844\2706685986.py", line 17, in <module>
    df[columna]=df['FLIGHTDATE'] + pd.to_datetime(df[columna], format='%H%M').dt.time
  File "C:\Users\alejo\AppData\Local\Packages\PythonSoftwareFoundation.Python.3.10_qbz5n2kfra8p0\LocalCache\local-packages\Python310\site-packages\pandas\core\tools\datetimes.py", line 1064, in to_datetime
    cache_array = _maybe_cache(arg, format, cache, convert_listlike)
  File "C:\Users\alejo\AppData\Local\Packages\PythonSoftwareFoundation.Python.3.10_qbz5n2kfra8p0\LocalCache\local-packages\Python310\site-packages\pandas\core\tools\datetimes.py", line 229, in _maybe_cache
    cache_dates = convert_listlike(unique_dates, format)
  File "C:\Users\alejo\AppData\Local\Packages\PythonSoftwareFoundation.Python.3.10_qbz5n2kfra8p0\LocalCache\local-packages\Python310\site-packages\pandas\core\tools\datetimes.py", line 430, in _convert_listlike_datetimes
    res = _to_datetime_with_format(
  File "C:\Users\alejo\AppData\Local\Packages\PythonSoftwareFoundation.Python.3.10_qbz5n2kfra8p0\LocalCache\local-packages\Python310\site-packages\pandas\core\tools\datetimes.py", line 538, in _to_datetime_with_format
    res = _array_strptime_with_fallback(
  File "C:\Users\alejo\AppData\Local\Packages\PythonSoftwareFoundation.Python.3.10_qbz5n2kfra8p0\LocalCache\local-packages\Python310\site-packages\pandas\core\tools\datetimes.py", line 473, in _array_strptime_with_fallback
    result, timezones = array_strptime(arg, fmt, exact=exact, errors=errors)
  File "pandas\_libs\tslibs\strptime.pyx", line 150, in pandas._libs.tslibs.strptime.array_strptime
ValueError: time data '0' does not match format '%H%M' (match)
2023-05-20 00:11:39,753 - ERROR - Se ha presentado una excepcion: time data '0' does not match format '%H%M' (match)
Traceback (most recent call last):
  File "C:\Users\alejo\AppData\Local\Temp\ipykernel_25844\2706685986.py", line 17, in <module>
    df[columna]=df['FLIGHTDATE'] + pd.to_datetime(df[columna], format='%H%M').dt.time
  File "C:\Users\alejo\AppData\Local\Packages\PythonSoftwareFoundation.Python.3.10_qbz5n2kfra8p0\LocalCache\local-packages\Python310\site-packages\pandas\core\tools\datetimes.py", line 1064, in to_datetime
    cache_array = _maybe_cache(arg, format, cache, convert_listlike)
  File "C:\Users\alejo\AppData\Local\Packages\PythonSoftwareFoundation.Python.3.10_qbz5n2kfra8p0\LocalCache\local-packages\Python310\site-packages\pandas\core\tools\datetimes.py", line 229, in _maybe_cache
    cache_dates = convert_listlike(unique_dates, format)
  File "C:\Users\alejo\AppData\Local\Packages\PythonSoftwareFoundation.Python.3.10_qbz5n2kfra8p0\LocalCache\local-packages\Python310\site-packages\pandas\core\tools\datetimes.py", line 430, in _convert_listlike_datetimes
    res = _to_datetime_with_format(
  File "C:\Users\alejo\AppData\Local\Packages\PythonSoftwareFoundation.Python.3.10_qbz5n2kfra8p0\LocalCache\local-packages\Python310\site-packages\pandas\core\tools\datetimes.py", line 538, in _to_datetime_with_format
    res = _array_strptime_with_fallback(
  File "C:\Users\alejo\AppData\Local\Packages\PythonSoftwareFoundation.Python.3.10_qbz5n2kfra8p0\LocalCache\local-packages\Python310\site-packages\pandas\core\tools\datetimes.py", line 473, in _array_strptime_with_fallback
    result, timezones = array_strptime(arg, fmt, exact=exact, errors=errors)
  File "pandas\_libs\tslibs\strptime.pyx", line 150, in pandas._libs.tslibs.strptime.array_strptime
ValueError: time data '0' does not match format '%H%M' (match)
2023-05-20 00:11:39,753 - ERROR - Se ha presentado una excepcion: time data '0' does not match format '%H%M' (match)
Traceback (most recent call last):
  File "C:\Users\alejo\AppData\Local\Temp\ipykernel_25844\2706685986.py", line 17, in <module>
    df[columna]=df['FLIGHTDATE'] + pd.to_datetime(df[columna], format='%H%M').dt.time
  File "C:\Users\alejo\AppData\Local\Packages\PythonSoftwareFoundation.Python.3.10_qbz5n2kfra8p0\LocalCache\local-packages\Python310\site-packages\pandas\core\tools\datetimes.py", line 1064, in to_datetime
    cache_array = _maybe_cache(arg, format, cache, convert_listlike)
  File "C:\Users\alejo\AppData\Local\Packages\PythonSoftwareFoundation.Python.3.10_qbz5n2kfra8p0\LocalCache\local-packages\Python310\site-packages\pandas\core\tools\datetimes.py", line 229, in _maybe_cache
    cache_dates = convert_listlike(unique_dates, format)
  File "C:\Users\alejo\AppData\Local\Packages\PythonSoftwareFoundation.Python.3.10_qbz5n2kfra8p0\LocalCache\local-packages\Python310\site-packages\pandas\core\tools\datetimes.py", line 430, in _convert_listlike_datetimes
    res = _to_datetime_with_format(
  File "C:\Users\alejo\AppData\Local\Packages\PythonSoftwareFoundation.Python.3.10_qbz5n2kfra8p0\LocalCache\local-packages\Python310\site-packages\pandas\core\tools\datetimes.py", line 538, in _to_datetime_with_format
    res = _array_strptime_with_fallback(
  File "C:\Users\alejo\AppData\Local\Packages\PythonSoftwareFoundation.Python.3.10_qbz5n2kfra8p0\LocalCache\local-packages\Python310\site-packages\pandas\core\tools\datetimes.py", line 473, in _array_strptime_with_fallback
    result, timezones = array_strptime(arg, fmt, exact=exact, errors=errors)
  File "pandas\_libs\tslibs\strptime.pyx", line 150, in pandas._libs.tslibs.strptime.array_strptime
ValueError: time data '0' does not match format '%H%M' (match)
2023-05-20 00:11:39,753 - ERROR - Se ha presentado una excepcion: time data '0' does not match format '%H%M' (match)
Traceback (most recent call last):
  File "C:\Users\alejo\AppData\Local\Temp\ipykernel_25844\2706685986.py", line 17, in <module>
    df[columna]=df['FLIGHTDATE'] + pd.to_datetime(df[columna], format='%H%M').dt.time
  File "C:\Users\alejo\AppData\Local\Packages\PythonSoftwareFoundation.Python.3.10_qbz5n2kfra8p0\LocalCache\local-packages\Python310\site-packages\pandas\core\tools\datetimes.py", line 1064, in to_datetime
    cache_array = _maybe_cache(arg, format, cache, convert_listlike)
  File "C:\Users\alejo\AppData\Local\Packages\PythonSoftwareFoundation.Python.3.10_qbz5n2kfra8p0\LocalCache\local-packages\Python310\site-packages\pandas\core\tools\datetimes.py", line 229, in _maybe_cache
    cache_dates = convert_listlike(unique_dates, format)
  File "C:\Users\alejo\AppData\Local\Packages\PythonSoftwareFoundation.Python.3.10_qbz5n2kfra8p0\LocalCache\local-packages\Python310\site-packages\pandas\core\tools\datetimes.py", line 430, in _convert_listlike_datetimes
    res = _to_datetime_with_format(
  File "C:\Users\alejo\AppData\Local\Packages\PythonSoftwareFoundation.Python.3.10_qbz5n2kfra8p0\LocalCache\local-packages\Python310\site-packages\pandas\core\tools\datetimes.py", line 538, in _to_datetime_with_format
    res = _array_strptime_with_fallback(
  File "C:\Users\alejo\AppData\Local\Packages\PythonSoftwareFoundation.Python.3.10_qbz5n2kfra8p0\LocalCache\local-packages\Python310\site-packages\pandas\core\tools\datetimes.py", line 473, in _array_strptime_with_fallback
    result, timezones = array_strptime(arg, fmt, exact=exact, errors=errors)
  File "pandas\_libs\tslibs\strptime.pyx", line 150, in pandas._libs.tslibs.strptime.array_strptime
ValueError: time data '0' does not match format '%H%M' (match)
2023-05-20 00:11:39,753 - ERROR - Se ha presentado una excepcion: time data '0' does not match format '%H%M' (match)
Traceback (most recent call last):
  File "C:\Users\alejo\AppData\Local\Temp\ipykernel_25844\2706685986.py", line 17, in <module>
    df[columna]=df['FLIGHTDATE'] + pd.to_datetime(df[columna], format='%H%M').dt.time
  File "C:\Users\alejo\AppData\Local\Packages\PythonSoftwareFoundation.Python.3.10_qbz5n2kfra8p0\LocalCache\local-packages\Python310\site-packages\pandas\core\tools\datetimes.py", line 1064, in to_datetime
    cache_array = _maybe_cache(arg, format, cache, convert_listlike)
  File "C:\Users\alejo\AppData\Local\Packages\PythonSoftwareFoundation.Python.3.10_qbz5n2kfra8p0\LocalCache\local-packages\Python310\site-packages\pandas\core\tools\datetimes.py", line 229, in _maybe_cache
    cache_dates = convert_listlike(unique_dates, format)
  File "C:\Users\alejo\AppData\Local\Packages\PythonSoftwareFoundation.Python.3.10_qbz5n2kfra8p0\LocalCache\local-packages\Python310\site-packages\pandas\core\tools\datetimes.py", line 430, in _convert_listlike_datetimes
    res = _to_datetime_with_format(
  File "C:\Users\alejo\AppData\Local\Packages\PythonSoftwareFoundation.Python.3.10_qbz5n2kfra8p0\LocalCache\local-packages\Python310\site-packages\pandas\core\tools\datetimes.py", line 538, in _to_datetime_with_format
    res = _array_strptime_with_fallback(
  File "C:\Users\alejo\AppData\Local\Packages\PythonSoftwareFoundation.Python.3.10_qbz5n2kfra8p0\LocalCache\local-packages\Python310\site-packages\pandas\core\tools\datetimes.py", line 473, in _array_strptime_with_fallback
    result, timezones = array_strptime(arg, fmt, exact=exact, errors=errors)
  File "pandas\_libs\tslibs\strptime.pyx", line 150, in pandas._libs.tslibs.strptime.array_strptime
ValueError: time data '0' does not match format '%H%M' (match)
2023-05-20 00:13:17,040 - ERROR - Se ha presentado una excepcion: Can only use .str accessor with string values!
Traceback (most recent call last):
  File "C:\Users\alejo\AppData\Local\Temp\ipykernel_25844\2190933915.py", line 6, in <module>
    df['DISTANCE']=df['DISTANCE'].str.replace(' miles', '')
  File "C:\Users\alejo\AppData\Local\Packages\PythonSoftwareFoundation.Python.3.10_qbz5n2kfra8p0\LocalCache\local-packages\Python310\site-packages\pandas\core\generic.py", line 5902, in __getattr__
    return object.__getattribute__(self, name)
  File "C:\Users\alejo\AppData\Local\Packages\PythonSoftwareFoundation.Python.3.10_qbz5n2kfra8p0\LocalCache\local-packages\Python310\site-packages\pandas\core\accessor.py", line 182, in __get__
    accessor_obj = self._accessor(obj)
  File "C:\Users\alejo\AppData\Local\Packages\PythonSoftwareFoundation.Python.3.10_qbz5n2kfra8p0\LocalCache\local-packages\Python310\site-packages\pandas\core\strings\accessor.py", line 181, in __init__
    self._inferred_dtype = self._validate(data)
  File "C:\Users\alejo\AppData\Local\Packages\PythonSoftwareFoundation.Python.3.10_qbz5n2kfra8p0\LocalCache\local-packages\Python310\site-packages\pandas\core\strings\accessor.py", line 235, in _validate
    raise AttributeError("Can only use .str accessor with string values!")
AttributeError: Can only use .str accessor with string values!
2023-05-20 00:13:17,040 - ERROR - Se ha presentado una excepcion: Can only use .str accessor with string values!
Traceback (most recent call last):
  File "C:\Users\alejo\AppData\Local\Temp\ipykernel_25844\2190933915.py", line 6, in <module>
    df['DISTANCE']=df['DISTANCE'].str.replace(' miles', '')
  File "C:\Users\alejo\AppData\Local\Packages\PythonSoftwareFoundation.Python.3.10_qbz5n2kfra8p0\LocalCache\local-packages\Python310\site-packages\pandas\core\generic.py", line 5902, in __getattr__
    return object.__getattribute__(self, name)
  File "C:\Users\alejo\AppData\Local\Packages\PythonSoftwareFoundation.Python.3.10_qbz5n2kfra8p0\LocalCache\local-packages\Python310\site-packages\pandas\core\accessor.py", line 182, in __get__
    accessor_obj = self._accessor(obj)
  File "C:\Users\alejo\AppData\Local\Packages\PythonSoftwareFoundation.Python.3.10_qbz5n2kfra8p0\LocalCache\local-packages\Python310\site-packages\pandas\core\strings\accessor.py", line 181, in __init__
    self._inferred_dtype = self._validate(data)
  File "C:\Users\alejo\AppData\Local\Packages\PythonSoftwareFoundation.Python.3.10_qbz5n2kfra8p0\LocalCache\local-packages\Python310\site-packages\pandas\core\strings\accessor.py", line 235, in _validate
    raise AttributeError("Can only use .str accessor with string values!")
AttributeError: Can only use .str accessor with string values!
2023-05-20 00:13:17,040 - ERROR - Se ha presentado una excepcion: Can only use .str accessor with string values!
Traceback (most recent call last):
  File "C:\Users\alejo\AppData\Local\Temp\ipykernel_25844\2190933915.py", line 6, in <module>
    df['DISTANCE']=df['DISTANCE'].str.replace(' miles', '')
  File "C:\Users\alejo\AppData\Local\Packages\PythonSoftwareFoundation.Python.3.10_qbz5n2kfra8p0\LocalCache\local-packages\Python310\site-packages\pandas\core\generic.py", line 5902, in __getattr__
    return object.__getattribute__(self, name)
  File "C:\Users\alejo\AppData\Local\Packages\PythonSoftwareFoundation.Python.3.10_qbz5n2kfra8p0\LocalCache\local-packages\Python310\site-packages\pandas\core\accessor.py", line 182, in __get__
    accessor_obj = self._accessor(obj)
  File "C:\Users\alejo\AppData\Local\Packages\PythonSoftwareFoundation.Python.3.10_qbz5n2kfra8p0\LocalCache\local-packages\Python310\site-packages\pandas\core\strings\accessor.py", line 181, in __init__
    self._inferred_dtype = self._validate(data)
  File "C:\Users\alejo\AppData\Local\Packages\PythonSoftwareFoundation.Python.3.10_qbz5n2kfra8p0\LocalCache\local-packages\Python310\site-packages\pandas\core\strings\accessor.py", line 235, in _validate
    raise AttributeError("Can only use .str accessor with string values!")
AttributeError: Can only use .str accessor with string values!
2023-05-20 00:13:17,040 - ERROR - Se ha presentado una excepcion: Can only use .str accessor with string values!
Traceback (most recent call last):
  File "C:\Users\alejo\AppData\Local\Temp\ipykernel_25844\2190933915.py", line 6, in <module>
    df['DISTANCE']=df['DISTANCE'].str.replace(' miles', '')
  File "C:\Users\alejo\AppData\Local\Packages\PythonSoftwareFoundation.Python.3.10_qbz5n2kfra8p0\LocalCache\local-packages\Python310\site-packages\pandas\core\generic.py", line 5902, in __getattr__
    return object.__getattribute__(self, name)
  File "C:\Users\alejo\AppData\Local\Packages\PythonSoftwareFoundation.Python.3.10_qbz5n2kfra8p0\LocalCache\local-packages\Python310\site-packages\pandas\core\accessor.py", line 182, in __get__
    accessor_obj = self._accessor(obj)
  File "C:\Users\alejo\AppData\Local\Packages\PythonSoftwareFoundation.Python.3.10_qbz5n2kfra8p0\LocalCache\local-packages\Python310\site-packages\pandas\core\strings\accessor.py", line 181, in __init__
    self._inferred_dtype = self._validate(data)
  File "C:\Users\alejo\AppData\Local\Packages\PythonSoftwareFoundation.Python.3.10_qbz5n2kfra8p0\LocalCache\local-packages\Python310\site-packages\pandas\core\strings\accessor.py", line 235, in _validate
    raise AttributeError("Can only use .str accessor with string values!")
AttributeError: Can only use .str accessor with string values!
2023-05-20 00:13:17,040 - ERROR - Se ha presentado una excepcion: Can only use .str accessor with string values!
Traceback (most recent call last):
  File "C:\Users\alejo\AppData\Local\Temp\ipykernel_25844\2190933915.py", line 6, in <module>
    df['DISTANCE']=df['DISTANCE'].str.replace(' miles', '')
  File "C:\Users\alejo\AppData\Local\Packages\PythonSoftwareFoundation.Python.3.10_qbz5n2kfra8p0\LocalCache\local-packages\Python310\site-packages\pandas\core\generic.py", line 5902, in __getattr__
    return object.__getattribute__(self, name)
  File "C:\Users\alejo\AppData\Local\Packages\PythonSoftwareFoundation.Python.3.10_qbz5n2kfra8p0\LocalCache\local-packages\Python310\site-packages\pandas\core\accessor.py", line 182, in __get__
    accessor_obj = self._accessor(obj)
  File "C:\Users\alejo\AppData\Local\Packages\PythonSoftwareFoundation.Python.3.10_qbz5n2kfra8p0\LocalCache\local-packages\Python310\site-packages\pandas\core\strings\accessor.py", line 181, in __init__
    self._inferred_dtype = self._validate(data)
  File "C:\Users\alejo\AppData\Local\Packages\PythonSoftwareFoundation.Python.3.10_qbz5n2kfra8p0\LocalCache\local-packages\Python310\site-packages\pandas\core\strings\accessor.py", line 235, in _validate
    raise AttributeError("Can only use .str accessor with string values!")
AttributeError: Can only use .str accessor with string values!
2023-05-20 00:13:32,201 - ERROR - Se ha presentado una excepcion: time data '0' does not match format '%H%M' (match)
Traceback (most recent call last):
  File "C:\Users\alejo\AppData\Local\Temp\ipykernel_25844\2190933915.py", line 18, in <module>
    df[columna]=df['FLIGHTDATE'] + pd.to_datetime(df[columna], format='%H%M').dt.time
  File "C:\Users\alejo\AppData\Local\Packages\PythonSoftwareFoundation.Python.3.10_qbz5n2kfra8p0\LocalCache\local-packages\Python310\site-packages\pandas\core\tools\datetimes.py", line 1064, in to_datetime
    cache_array = _maybe_cache(arg, format, cache, convert_listlike)
  File "C:\Users\alejo\AppData\Local\Packages\PythonSoftwareFoundation.Python.3.10_qbz5n2kfra8p0\LocalCache\local-packages\Python310\site-packages\pandas\core\tools\datetimes.py", line 229, in _maybe_cache
    cache_dates = convert_listlike(unique_dates, format)
  File "C:\Users\alejo\AppData\Local\Packages\PythonSoftwareFoundation.Python.3.10_qbz5n2kfra8p0\LocalCache\local-packages\Python310\site-packages\pandas\core\tools\datetimes.py", line 430, in _convert_listlike_datetimes
    res = _to_datetime_with_format(
  File "C:\Users\alejo\AppData\Local\Packages\PythonSoftwareFoundation.Python.3.10_qbz5n2kfra8p0\LocalCache\local-packages\Python310\site-packages\pandas\core\tools\datetimes.py", line 538, in _to_datetime_with_format
    res = _array_strptime_with_fallback(
  File "C:\Users\alejo\AppData\Local\Packages\PythonSoftwareFoundation.Python.3.10_qbz5n2kfra8p0\LocalCache\local-packages\Python310\site-packages\pandas\core\tools\datetimes.py", line 473, in _array_strptime_with_fallback
    result, timezones = array_strptime(arg, fmt, exact=exact, errors=errors)
  File "pandas\_libs\tslibs\strptime.pyx", line 150, in pandas._libs.tslibs.strptime.array_strptime
ValueError: time data '0' does not match format '%H%M' (match)
2023-05-20 00:13:32,201 - ERROR - Se ha presentado una excepcion: time data '0' does not match format '%H%M' (match)
Traceback (most recent call last):
  File "C:\Users\alejo\AppData\Local\Temp\ipykernel_25844\2190933915.py", line 18, in <module>
    df[columna]=df['FLIGHTDATE'] + pd.to_datetime(df[columna], format='%H%M').dt.time
  File "C:\Users\alejo\AppData\Local\Packages\PythonSoftwareFoundation.Python.3.10_qbz5n2kfra8p0\LocalCache\local-packages\Python310\site-packages\pandas\core\tools\datetimes.py", line 1064, in to_datetime
    cache_array = _maybe_cache(arg, format, cache, convert_listlike)
  File "C:\Users\alejo\AppData\Local\Packages\PythonSoftwareFoundation.Python.3.10_qbz5n2kfra8p0\LocalCache\local-packages\Python310\site-packages\pandas\core\tools\datetimes.py", line 229, in _maybe_cache
    cache_dates = convert_listlike(unique_dates, format)
  File "C:\Users\alejo\AppData\Local\Packages\PythonSoftwareFoundation.Python.3.10_qbz5n2kfra8p0\LocalCache\local-packages\Python310\site-packages\pandas\core\tools\datetimes.py", line 430, in _convert_listlike_datetimes
    res = _to_datetime_with_format(
  File "C:\Users\alejo\AppData\Local\Packages\PythonSoftwareFoundation.Python.3.10_qbz5n2kfra8p0\LocalCache\local-packages\Python310\site-packages\pandas\core\tools\datetimes.py", line 538, in _to_datetime_with_format
    res = _array_strptime_with_fallback(
  File "C:\Users\alejo\AppData\Local\Packages\PythonSoftwareFoundation.Python.3.10_qbz5n2kfra8p0\LocalCache\local-packages\Python310\site-packages\pandas\core\tools\datetimes.py", line 473, in _array_strptime_with_fallback
    result, timezones = array_strptime(arg, fmt, exact=exact, errors=errors)
  File "pandas\_libs\tslibs\strptime.pyx", line 150, in pandas._libs.tslibs.strptime.array_strptime
ValueError: time data '0' does not match format '%H%M' (match)
2023-05-20 00:13:32,201 - ERROR - Se ha presentado una excepcion: time data '0' does not match format '%H%M' (match)
Traceback (most recent call last):
  File "C:\Users\alejo\AppData\Local\Temp\ipykernel_25844\2190933915.py", line 18, in <module>
    df[columna]=df['FLIGHTDATE'] + pd.to_datetime(df[columna], format='%H%M').dt.time
  File "C:\Users\alejo\AppData\Local\Packages\PythonSoftwareFoundation.Python.3.10_qbz5n2kfra8p0\LocalCache\local-packages\Python310\site-packages\pandas\core\tools\datetimes.py", line 1064, in to_datetime
    cache_array = _maybe_cache(arg, format, cache, convert_listlike)
  File "C:\Users\alejo\AppData\Local\Packages\PythonSoftwareFoundation.Python.3.10_qbz5n2kfra8p0\LocalCache\local-packages\Python310\site-packages\pandas\core\tools\datetimes.py", line 229, in _maybe_cache
    cache_dates = convert_listlike(unique_dates, format)
  File "C:\Users\alejo\AppData\Local\Packages\PythonSoftwareFoundation.Python.3.10_qbz5n2kfra8p0\LocalCache\local-packages\Python310\site-packages\pandas\core\tools\datetimes.py", line 430, in _convert_listlike_datetimes
    res = _to_datetime_with_format(
  File "C:\Users\alejo\AppData\Local\Packages\PythonSoftwareFoundation.Python.3.10_qbz5n2kfra8p0\LocalCache\local-packages\Python310\site-packages\pandas\core\tools\datetimes.py", line 538, in _to_datetime_with_format
    res = _array_strptime_with_fallback(
  File "C:\Users\alejo\AppData\Local\Packages\PythonSoftwareFoundation.Python.3.10_qbz5n2kfra8p0\LocalCache\local-packages\Python310\site-packages\pandas\core\tools\datetimes.py", line 473, in _array_strptime_with_fallback
    result, timezones = array_strptime(arg, fmt, exact=exact, errors=errors)
  File "pandas\_libs\tslibs\strptime.pyx", line 150, in pandas._libs.tslibs.strptime.array_strptime
ValueError: time data '0' does not match format '%H%M' (match)
2023-05-20 00:13:32,201 - ERROR - Se ha presentado una excepcion: time data '0' does not match format '%H%M' (match)
Traceback (most recent call last):
  File "C:\Users\alejo\AppData\Local\Temp\ipykernel_25844\2190933915.py", line 18, in <module>
    df[columna]=df['FLIGHTDATE'] + pd.to_datetime(df[columna], format='%H%M').dt.time
  File "C:\Users\alejo\AppData\Local\Packages\PythonSoftwareFoundation.Python.3.10_qbz5n2kfra8p0\LocalCache\local-packages\Python310\site-packages\pandas\core\tools\datetimes.py", line 1064, in to_datetime
    cache_array = _maybe_cache(arg, format, cache, convert_listlike)
  File "C:\Users\alejo\AppData\Local\Packages\PythonSoftwareFoundation.Python.3.10_qbz5n2kfra8p0\LocalCache\local-packages\Python310\site-packages\pandas\core\tools\datetimes.py", line 229, in _maybe_cache
    cache_dates = convert_listlike(unique_dates, format)
  File "C:\Users\alejo\AppData\Local\Packages\PythonSoftwareFoundation.Python.3.10_qbz5n2kfra8p0\LocalCache\local-packages\Python310\site-packages\pandas\core\tools\datetimes.py", line 430, in _convert_listlike_datetimes
    res = _to_datetime_with_format(
  File "C:\Users\alejo\AppData\Local\Packages\PythonSoftwareFoundation.Python.3.10_qbz5n2kfra8p0\LocalCache\local-packages\Python310\site-packages\pandas\core\tools\datetimes.py", line 538, in _to_datetime_with_format
    res = _array_strptime_with_fallback(
  File "C:\Users\alejo\AppData\Local\Packages\PythonSoftwareFoundation.Python.3.10_qbz5n2kfra8p0\LocalCache\local-packages\Python310\site-packages\pandas\core\tools\datetimes.py", line 473, in _array_strptime_with_fallback
    result, timezones = array_strptime(arg, fmt, exact=exact, errors=errors)
  File "pandas\_libs\tslibs\strptime.pyx", line 150, in pandas._libs.tslibs.strptime.array_strptime
ValueError: time data '0' does not match format '%H%M' (match)
2023-05-20 00:13:32,201 - ERROR - Se ha presentado una excepcion: time data '0' does not match format '%H%M' (match)
Traceback (most recent call last):
  File "C:\Users\alejo\AppData\Local\Temp\ipykernel_25844\2190933915.py", line 18, in <module>
    df[columna]=df['FLIGHTDATE'] + pd.to_datetime(df[columna], format='%H%M').dt.time
  File "C:\Users\alejo\AppData\Local\Packages\PythonSoftwareFoundation.Python.3.10_qbz5n2kfra8p0\LocalCache\local-packages\Python310\site-packages\pandas\core\tools\datetimes.py", line 1064, in to_datetime
    cache_array = _maybe_cache(arg, format, cache, convert_listlike)
  File "C:\Users\alejo\AppData\Local\Packages\PythonSoftwareFoundation.Python.3.10_qbz5n2kfra8p0\LocalCache\local-packages\Python310\site-packages\pandas\core\tools\datetimes.py", line 229, in _maybe_cache
    cache_dates = convert_listlike(unique_dates, format)
  File "C:\Users\alejo\AppData\Local\Packages\PythonSoftwareFoundation.Python.3.10_qbz5n2kfra8p0\LocalCache\local-packages\Python310\site-packages\pandas\core\tools\datetimes.py", line 430, in _convert_listlike_datetimes
    res = _to_datetime_with_format(
  File "C:\Users\alejo\AppData\Local\Packages\PythonSoftwareFoundation.Python.3.10_qbz5n2kfra8p0\LocalCache\local-packages\Python310\site-packages\pandas\core\tools\datetimes.py", line 538, in _to_datetime_with_format
    res = _array_strptime_with_fallback(
  File "C:\Users\alejo\AppData\Local\Packages\PythonSoftwareFoundation.Python.3.10_qbz5n2kfra8p0\LocalCache\local-packages\Python310\site-packages\pandas\core\tools\datetimes.py", line 473, in _array_strptime_with_fallback
    result, timezones = array_strptime(arg, fmt, exact=exact, errors=errors)
  File "pandas\_libs\tslibs\strptime.pyx", line 150, in pandas._libs.tslibs.strptime.array_strptime
ValueError: time data '0' does not match format '%H%M' (match)
2023-05-20 00:13:32,201 - ERROR - Se ha presentado una excepcion: time data '0' does not match format '%H%M' (match)
Traceback (most recent call last):
  File "C:\Users\alejo\AppData\Local\Temp\ipykernel_25844\2190933915.py", line 18, in <module>
    df[columna]=df['FLIGHTDATE'] + pd.to_datetime(df[columna], format='%H%M').dt.time
  File "C:\Users\alejo\AppData\Local\Packages\PythonSoftwareFoundation.Python.3.10_qbz5n2kfra8p0\LocalCache\local-packages\Python310\site-packages\pandas\core\tools\datetimes.py", line 1064, in to_datetime
    cache_array = _maybe_cache(arg, format, cache, convert_listlike)
  File "C:\Users\alejo\AppData\Local\Packages\PythonSoftwareFoundation.Python.3.10_qbz5n2kfra8p0\LocalCache\local-packages\Python310\site-packages\pandas\core\tools\datetimes.py", line 229, in _maybe_cache
    cache_dates = convert_listlike(unique_dates, format)
  File "C:\Users\alejo\AppData\Local\Packages\PythonSoftwareFoundation.Python.3.10_qbz5n2kfra8p0\LocalCache\local-packages\Python310\site-packages\pandas\core\tools\datetimes.py", line 430, in _convert_listlike_datetimes
    res = _to_datetime_with_format(
  File "C:\Users\alejo\AppData\Local\Packages\PythonSoftwareFoundation.Python.3.10_qbz5n2kfra8p0\LocalCache\local-packages\Python310\site-packages\pandas\core\tools\datetimes.py", line 538, in _to_datetime_with_format
    res = _array_strptime_with_fallback(
  File "C:\Users\alejo\AppData\Local\Packages\PythonSoftwareFoundation.Python.3.10_qbz5n2kfra8p0\LocalCache\local-packages\Python310\site-packages\pandas\core\tools\datetimes.py", line 473, in _array_strptime_with_fallback
    result, timezones = array_strptime(arg, fmt, exact=exact, errors=errors)
  File "pandas\_libs\tslibs\strptime.pyx", line 150, in pandas._libs.tslibs.strptime.array_strptime
ValueError: time data '0' does not match format '%H%M' (match)
2023-05-20 00:16:26,958 - ERROR - Se ha presentado una excepcion: time data '0' does not match format '%H%M' (match)
Traceback (most recent call last):
  File "C:\Users\alejo\AppData\Local\Temp\ipykernel_25844\2190933915.py", line 18, in <module>
    df[columna]=df['FLIGHTDATE'] + pd.to_datetime(df[columna], format='%H%M').dt.time
  File "C:\Users\alejo\AppData\Local\Packages\PythonSoftwareFoundation.Python.3.10_qbz5n2kfra8p0\LocalCache\local-packages\Python310\site-packages\pandas\core\tools\datetimes.py", line 1064, in to_datetime
    cache_array = _maybe_cache(arg, format, cache, convert_listlike)
  File "C:\Users\alejo\AppData\Local\Packages\PythonSoftwareFoundation.Python.3.10_qbz5n2kfra8p0\LocalCache\local-packages\Python310\site-packages\pandas\core\tools\datetimes.py", line 229, in _maybe_cache
    cache_dates = convert_listlike(unique_dates, format)
  File "C:\Users\alejo\AppData\Local\Packages\PythonSoftwareFoundation.Python.3.10_qbz5n2kfra8p0\LocalCache\local-packages\Python310\site-packages\pandas\core\tools\datetimes.py", line 430, in _convert_listlike_datetimes
    res = _to_datetime_with_format(
  File "C:\Users\alejo\AppData\Local\Packages\PythonSoftwareFoundation.Python.3.10_qbz5n2kfra8p0\LocalCache\local-packages\Python310\site-packages\pandas\core\tools\datetimes.py", line 538, in _to_datetime_with_format
    res = _array_strptime_with_fallback(
  File "C:\Users\alejo\AppData\Local\Packages\PythonSoftwareFoundation.Python.3.10_qbz5n2kfra8p0\LocalCache\local-packages\Python310\site-packages\pandas\core\tools\datetimes.py", line 473, in _array_strptime_with_fallback
    result, timezones = array_strptime(arg, fmt, exact=exact, errors=errors)
  File "pandas\_libs\tslibs\strptime.pyx", line 150, in pandas._libs.tslibs.strptime.array_strptime
ValueError: time data '0' does not match format '%H%M' (match)
2023-05-20 00:16:26,958 - ERROR - Se ha presentado una excepcion: time data '0' does not match format '%H%M' (match)
Traceback (most recent call last):
  File "C:\Users\alejo\AppData\Local\Temp\ipykernel_25844\2190933915.py", line 18, in <module>
    df[columna]=df['FLIGHTDATE'] + pd.to_datetime(df[columna], format='%H%M').dt.time
  File "C:\Users\alejo\AppData\Local\Packages\PythonSoftwareFoundation.Python.3.10_qbz5n2kfra8p0\LocalCache\local-packages\Python310\site-packages\pandas\core\tools\datetimes.py", line 1064, in to_datetime
    cache_array = _maybe_cache(arg, format, cache, convert_listlike)
  File "C:\Users\alejo\AppData\Local\Packages\PythonSoftwareFoundation.Python.3.10_qbz5n2kfra8p0\LocalCache\local-packages\Python310\site-packages\pandas\core\tools\datetimes.py", line 229, in _maybe_cache
    cache_dates = convert_listlike(unique_dates, format)
  File "C:\Users\alejo\AppData\Local\Packages\PythonSoftwareFoundation.Python.3.10_qbz5n2kfra8p0\LocalCache\local-packages\Python310\site-packages\pandas\core\tools\datetimes.py", line 430, in _convert_listlike_datetimes
    res = _to_datetime_with_format(
  File "C:\Users\alejo\AppData\Local\Packages\PythonSoftwareFoundation.Python.3.10_qbz5n2kfra8p0\LocalCache\local-packages\Python310\site-packages\pandas\core\tools\datetimes.py", line 538, in _to_datetime_with_format
    res = _array_strptime_with_fallback(
  File "C:\Users\alejo\AppData\Local\Packages\PythonSoftwareFoundation.Python.3.10_qbz5n2kfra8p0\LocalCache\local-packages\Python310\site-packages\pandas\core\tools\datetimes.py", line 473, in _array_strptime_with_fallback
    result, timezones = array_strptime(arg, fmt, exact=exact, errors=errors)
  File "pandas\_libs\tslibs\strptime.pyx", line 150, in pandas._libs.tslibs.strptime.array_strptime
ValueError: time data '0' does not match format '%H%M' (match)
2023-05-20 00:16:26,958 - ERROR - Se ha presentado una excepcion: time data '0' does not match format '%H%M' (match)
Traceback (most recent call last):
  File "C:\Users\alejo\AppData\Local\Temp\ipykernel_25844\2190933915.py", line 18, in <module>
    df[columna]=df['FLIGHTDATE'] + pd.to_datetime(df[columna], format='%H%M').dt.time
  File "C:\Users\alejo\AppData\Local\Packages\PythonSoftwareFoundation.Python.3.10_qbz5n2kfra8p0\LocalCache\local-packages\Python310\site-packages\pandas\core\tools\datetimes.py", line 1064, in to_datetime
    cache_array = _maybe_cache(arg, format, cache, convert_listlike)
  File "C:\Users\alejo\AppData\Local\Packages\PythonSoftwareFoundation.Python.3.10_qbz5n2kfra8p0\LocalCache\local-packages\Python310\site-packages\pandas\core\tools\datetimes.py", line 229, in _maybe_cache
    cache_dates = convert_listlike(unique_dates, format)
  File "C:\Users\alejo\AppData\Local\Packages\PythonSoftwareFoundation.Python.3.10_qbz5n2kfra8p0\LocalCache\local-packages\Python310\site-packages\pandas\core\tools\datetimes.py", line 430, in _convert_listlike_datetimes
    res = _to_datetime_with_format(
  File "C:\Users\alejo\AppData\Local\Packages\PythonSoftwareFoundation.Python.3.10_qbz5n2kfra8p0\LocalCache\local-packages\Python310\site-packages\pandas\core\tools\datetimes.py", line 538, in _to_datetime_with_format
    res = _array_strptime_with_fallback(
  File "C:\Users\alejo\AppData\Local\Packages\PythonSoftwareFoundation.Python.3.10_qbz5n2kfra8p0\LocalCache\local-packages\Python310\site-packages\pandas\core\tools\datetimes.py", line 473, in _array_strptime_with_fallback
    result, timezones = array_strptime(arg, fmt, exact=exact, errors=errors)
  File "pandas\_libs\tslibs\strptime.pyx", line 150, in pandas._libs.tslibs.strptime.array_strptime
ValueError: time data '0' does not match format '%H%M' (match)
2023-05-20 00:16:26,958 - ERROR - Se ha presentado una excepcion: time data '0' does not match format '%H%M' (match)
Traceback (most recent call last):
  File "C:\Users\alejo\AppData\Local\Temp\ipykernel_25844\2190933915.py", line 18, in <module>
    df[columna]=df['FLIGHTDATE'] + pd.to_datetime(df[columna], format='%H%M').dt.time
  File "C:\Users\alejo\AppData\Local\Packages\PythonSoftwareFoundation.Python.3.10_qbz5n2kfra8p0\LocalCache\local-packages\Python310\site-packages\pandas\core\tools\datetimes.py", line 1064, in to_datetime
    cache_array = _maybe_cache(arg, format, cache, convert_listlike)
  File "C:\Users\alejo\AppData\Local\Packages\PythonSoftwareFoundation.Python.3.10_qbz5n2kfra8p0\LocalCache\local-packages\Python310\site-packages\pandas\core\tools\datetimes.py", line 229, in _maybe_cache
    cache_dates = convert_listlike(unique_dates, format)
  File "C:\Users\alejo\AppData\Local\Packages\PythonSoftwareFoundation.Python.3.10_qbz5n2kfra8p0\LocalCache\local-packages\Python310\site-packages\pandas\core\tools\datetimes.py", line 430, in _convert_listlike_datetimes
    res = _to_datetime_with_format(
  File "C:\Users\alejo\AppData\Local\Packages\PythonSoftwareFoundation.Python.3.10_qbz5n2kfra8p0\LocalCache\local-packages\Python310\site-packages\pandas\core\tools\datetimes.py", line 538, in _to_datetime_with_format
    res = _array_strptime_with_fallback(
  File "C:\Users\alejo\AppData\Local\Packages\PythonSoftwareFoundation.Python.3.10_qbz5n2kfra8p0\LocalCache\local-packages\Python310\site-packages\pandas\core\tools\datetimes.py", line 473, in _array_strptime_with_fallback
    result, timezones = array_strptime(arg, fmt, exact=exact, errors=errors)
  File "pandas\_libs\tslibs\strptime.pyx", line 150, in pandas._libs.tslibs.strptime.array_strptime
ValueError: time data '0' does not match format '%H%M' (match)
2023-05-20 00:16:26,958 - ERROR - Se ha presentado una excepcion: time data '0' does not match format '%H%M' (match)
Traceback (most recent call last):
  File "C:\Users\alejo\AppData\Local\Temp\ipykernel_25844\2190933915.py", line 18, in <module>
    df[columna]=df['FLIGHTDATE'] + pd.to_datetime(df[columna], format='%H%M').dt.time
  File "C:\Users\alejo\AppData\Local\Packages\PythonSoftwareFoundation.Python.3.10_qbz5n2kfra8p0\LocalCache\local-packages\Python310\site-packages\pandas\core\tools\datetimes.py", line 1064, in to_datetime
    cache_array = _maybe_cache(arg, format, cache, convert_listlike)
  File "C:\Users\alejo\AppData\Local\Packages\PythonSoftwareFoundation.Python.3.10_qbz5n2kfra8p0\LocalCache\local-packages\Python310\site-packages\pandas\core\tools\datetimes.py", line 229, in _maybe_cache
    cache_dates = convert_listlike(unique_dates, format)
  File "C:\Users\alejo\AppData\Local\Packages\PythonSoftwareFoundation.Python.3.10_qbz5n2kfra8p0\LocalCache\local-packages\Python310\site-packages\pandas\core\tools\datetimes.py", line 430, in _convert_listlike_datetimes
    res = _to_datetime_with_format(
  File "C:\Users\alejo\AppData\Local\Packages\PythonSoftwareFoundation.Python.3.10_qbz5n2kfra8p0\LocalCache\local-packages\Python310\site-packages\pandas\core\tools\datetimes.py", line 538, in _to_datetime_with_format
    res = _array_strptime_with_fallback(
  File "C:\Users\alejo\AppData\Local\Packages\PythonSoftwareFoundation.Python.3.10_qbz5n2kfra8p0\LocalCache\local-packages\Python310\site-packages\pandas\core\tools\datetimes.py", line 473, in _array_strptime_with_fallback
    result, timezones = array_strptime(arg, fmt, exact=exact, errors=errors)
  File "pandas\_libs\tslibs\strptime.pyx", line 150, in pandas._libs.tslibs.strptime.array_strptime
ValueError: time data '0' does not match format '%H%M' (match)
2023-05-20 00:16:26,958 - ERROR - Se ha presentado una excepcion: time data '0' does not match format '%H%M' (match)
Traceback (most recent call last):
  File "C:\Users\alejo\AppData\Local\Temp\ipykernel_25844\2190933915.py", line 18, in <module>
    df[columna]=df['FLIGHTDATE'] + pd.to_datetime(df[columna], format='%H%M').dt.time
  File "C:\Users\alejo\AppData\Local\Packages\PythonSoftwareFoundation.Python.3.10_qbz5n2kfra8p0\LocalCache\local-packages\Python310\site-packages\pandas\core\tools\datetimes.py", line 1064, in to_datetime
    cache_array = _maybe_cache(arg, format, cache, convert_listlike)
  File "C:\Users\alejo\AppData\Local\Packages\PythonSoftwareFoundation.Python.3.10_qbz5n2kfra8p0\LocalCache\local-packages\Python310\site-packages\pandas\core\tools\datetimes.py", line 229, in _maybe_cache
    cache_dates = convert_listlike(unique_dates, format)
  File "C:\Users\alejo\AppData\Local\Packages\PythonSoftwareFoundation.Python.3.10_qbz5n2kfra8p0\LocalCache\local-packages\Python310\site-packages\pandas\core\tools\datetimes.py", line 430, in _convert_listlike_datetimes
    res = _to_datetime_with_format(
  File "C:\Users\alejo\AppData\Local\Packages\PythonSoftwareFoundation.Python.3.10_qbz5n2kfra8p0\LocalCache\local-packages\Python310\site-packages\pandas\core\tools\datetimes.py", line 538, in _to_datetime_with_format
    res = _array_strptime_with_fallback(
  File "C:\Users\alejo\AppData\Local\Packages\PythonSoftwareFoundation.Python.3.10_qbz5n2kfra8p0\LocalCache\local-packages\Python310\site-packages\pandas\core\tools\datetimes.py", line 473, in _array_strptime_with_fallback
    result, timezones = array_strptime(arg, fmt, exact=exact, errors=errors)
  File "pandas\_libs\tslibs\strptime.pyx", line 150, in pandas._libs.tslibs.strptime.array_strptime
ValueError: time data '0' does not match format '%H%M' (match)
2023-05-20 00:16:26,958 - ERROR - Se ha presentado una excepcion: time data '0' does not match format '%H%M' (match)
Traceback (most recent call last):
  File "C:\Users\alejo\AppData\Local\Temp\ipykernel_25844\2190933915.py", line 18, in <module>
    df[columna]=df['FLIGHTDATE'] + pd.to_datetime(df[columna], format='%H%M').dt.time
  File "C:\Users\alejo\AppData\Local\Packages\PythonSoftwareFoundation.Python.3.10_qbz5n2kfra8p0\LocalCache\local-packages\Python310\site-packages\pandas\core\tools\datetimes.py", line 1064, in to_datetime
    cache_array = _maybe_cache(arg, format, cache, convert_listlike)
  File "C:\Users\alejo\AppData\Local\Packages\PythonSoftwareFoundation.Python.3.10_qbz5n2kfra8p0\LocalCache\local-packages\Python310\site-packages\pandas\core\tools\datetimes.py", line 229, in _maybe_cache
    cache_dates = convert_listlike(unique_dates, format)
  File "C:\Users\alejo\AppData\Local\Packages\PythonSoftwareFoundation.Python.3.10_qbz5n2kfra8p0\LocalCache\local-packages\Python310\site-packages\pandas\core\tools\datetimes.py", line 430, in _convert_listlike_datetimes
    res = _to_datetime_with_format(
  File "C:\Users\alejo\AppData\Local\Packages\PythonSoftwareFoundation.Python.3.10_qbz5n2kfra8p0\LocalCache\local-packages\Python310\site-packages\pandas\core\tools\datetimes.py", line 538, in _to_datetime_with_format
    res = _array_strptime_with_fallback(
  File "C:\Users\alejo\AppData\Local\Packages\PythonSoftwareFoundation.Python.3.10_qbz5n2kfra8p0\LocalCache\local-packages\Python310\site-packages\pandas\core\tools\datetimes.py", line 473, in _array_strptime_with_fallback
    result, timezones = array_strptime(arg, fmt, exact=exact, errors=errors)
  File "pandas\_libs\tslibs\strptime.pyx", line 150, in pandas._libs.tslibs.strptime.array_strptime
ValueError: time data '0' does not match format '%H%M' (match)
2023-05-20 00:16:26,958 - ERROR - Se ha presentado una excepcion: time data '0' does not match format '%H%M' (match)
Traceback (most recent call last):
  File "C:\Users\alejo\AppData\Local\Temp\ipykernel_25844\2190933915.py", line 18, in <module>
    df[columna]=df['FLIGHTDATE'] + pd.to_datetime(df[columna], format='%H%M').dt.time
  File "C:\Users\alejo\AppData\Local\Packages\PythonSoftwareFoundation.Python.3.10_qbz5n2kfra8p0\LocalCache\local-packages\Python310\site-packages\pandas\core\tools\datetimes.py", line 1064, in to_datetime
    cache_array = _maybe_cache(arg, format, cache, convert_listlike)
  File "C:\Users\alejo\AppData\Local\Packages\PythonSoftwareFoundation.Python.3.10_qbz5n2kfra8p0\LocalCache\local-packages\Python310\site-packages\pandas\core\tools\datetimes.py", line 229, in _maybe_cache
    cache_dates = convert_listlike(unique_dates, format)
  File "C:\Users\alejo\AppData\Local\Packages\PythonSoftwareFoundation.Python.3.10_qbz5n2kfra8p0\LocalCache\local-packages\Python310\site-packages\pandas\core\tools\datetimes.py", line 430, in _convert_listlike_datetimes
    res = _to_datetime_with_format(
  File "C:\Users\alejo\AppData\Local\Packages\PythonSoftwareFoundation.Python.3.10_qbz5n2kfra8p0\LocalCache\local-packages\Python310\site-packages\pandas\core\tools\datetimes.py", line 538, in _to_datetime_with_format
    res = _array_strptime_with_fallback(
  File "C:\Users\alejo\AppData\Local\Packages\PythonSoftwareFoundation.Python.3.10_qbz5n2kfra8p0\LocalCache\local-packages\Python310\site-packages\pandas\core\tools\datetimes.py", line 473, in _array_strptime_with_fallback
    result, timezones = array_strptime(arg, fmt, exact=exact, errors=errors)
  File "pandas\_libs\tslibs\strptime.pyx", line 150, in pandas._libs.tslibs.strptime.array_strptime
ValueError: time data '0' does not match format '%H%M' (match)
2023-05-20 05:05:14,138 - ERROR - Se ha presentado una excepcion: 'Series' object has no attribute 'strftime'
Traceback (most recent call last):
  File "C:\Users\alejo\AppData\Local\Temp\ipykernel_16728\649345370.py", line 8, in <module>
    df['TAXIOUT']=pd.to_timedelta(df['TAXIOUT'], unit='min',errors='ignore').strftime('%M')
  File "C:\Users\alejo\AppData\Local\Packages\PythonSoftwareFoundation.Python.3.10_qbz5n2kfra8p0\LocalCache\local-packages\Python310\site-packages\pandas\core\generic.py", line 5902, in __getattr__
    return object.__getattribute__(self, name)
AttributeError: 'Series' object has no attribute 'strftime'
2023-05-20 05:05:14,138 - ERROR - Se ha presentado una excepcion: 'Series' object has no attribute 'strftime'
Traceback (most recent call last):
  File "C:\Users\alejo\AppData\Local\Temp\ipykernel_16728\649345370.py", line 8, in <module>
    df['TAXIOUT']=pd.to_timedelta(df['TAXIOUT'], unit='min',errors='ignore').strftime('%M')
  File "C:\Users\alejo\AppData\Local\Packages\PythonSoftwareFoundation.Python.3.10_qbz5n2kfra8p0\LocalCache\local-packages\Python310\site-packages\pandas\core\generic.py", line 5902, in __getattr__
    return object.__getattribute__(self, name)
AttributeError: 'Series' object has no attribute 'strftime'
2023-05-20 05:06:09,648 - ERROR - Se ha presentado una excepcion: 'Series' object has no attribute 'as_unit'
Traceback (most recent call last):
  File "C:\Users\alejo\AppData\Local\Temp\ipykernel_16728\2444189440.py", line 9, in <module>
    df['TAXIOUT']=df['TAXIOUT'].as_unit()
  File "C:\Users\alejo\AppData\Local\Packages\PythonSoftwareFoundation.Python.3.10_qbz5n2kfra8p0\LocalCache\local-packages\Python310\site-packages\pandas\core\generic.py", line 5902, in __getattr__
    return object.__getattribute__(self, name)
AttributeError: 'Series' object has no attribute 'as_unit'
2023-05-20 05:06:09,648 - ERROR - Se ha presentado una excepcion: 'Series' object has no attribute 'as_unit'
Traceback (most recent call last):
  File "C:\Users\alejo\AppData\Local\Temp\ipykernel_16728\2444189440.py", line 9, in <module>
    df['TAXIOUT']=df['TAXIOUT'].as_unit()
  File "C:\Users\alejo\AppData\Local\Packages\PythonSoftwareFoundation.Python.3.10_qbz5n2kfra8p0\LocalCache\local-packages\Python310\site-packages\pandas\core\generic.py", line 5902, in __getattr__
    return object.__getattribute__(self, name)
AttributeError: 'Series' object has no attribute 'as_unit'
2023-05-20 05:06:09,648 - ERROR - Se ha presentado una excepcion: 'Series' object has no attribute 'as_unit'
Traceback (most recent call last):
  File "C:\Users\alejo\AppData\Local\Temp\ipykernel_16728\2444189440.py", line 9, in <module>
    df['TAXIOUT']=df['TAXIOUT'].as_unit()
  File "C:\Users\alejo\AppData\Local\Packages\PythonSoftwareFoundation.Python.3.10_qbz5n2kfra8p0\LocalCache\local-packages\Python310\site-packages\pandas\core\generic.py", line 5902, in __getattr__
    return object.__getattribute__(self, name)
AttributeError: 'Series' object has no attribute 'as_unit'
2023-05-20 05:10:21,723 - ERROR - Se ha presentado una excepcion: 'TimedeltaProperties' object has no attribute 'minute'
Traceback (most recent call last):
  File "C:\Users\alejo\AppData\Local\Temp\ipykernel_16728\4007228666.py", line 9, in <module>
    df['TAXIOUT']=df['TAXIOUT'].dt.minute
AttributeError: 'TimedeltaProperties' object has no attribute 'minute'
2023-05-20 05:10:21,723 - ERROR - Se ha presentado una excepcion: 'TimedeltaProperties' object has no attribute 'minute'
Traceback (most recent call last):
  File "C:\Users\alejo\AppData\Local\Temp\ipykernel_16728\4007228666.py", line 9, in <module>
    df['TAXIOUT']=df['TAXIOUT'].dt.minute
AttributeError: 'TimedeltaProperties' object has no attribute 'minute'
2023-05-20 05:10:21,723 - ERROR - Se ha presentado una excepcion: 'TimedeltaProperties' object has no attribute 'minute'
Traceback (most recent call last):
  File "C:\Users\alejo\AppData\Local\Temp\ipykernel_16728\4007228666.py", line 9, in <module>
    df['TAXIOUT']=df['TAXIOUT'].dt.minute
AttributeError: 'TimedeltaProperties' object has no attribute 'minute'
2023-05-20 05:10:21,723 - ERROR - Se ha presentado una excepcion: 'TimedeltaProperties' object has no attribute 'minute'
Traceback (most recent call last):
  File "C:\Users\alejo\AppData\Local\Temp\ipykernel_16728\4007228666.py", line 9, in <module>
    df['TAXIOUT']=df['TAXIOUT'].dt.minute
AttributeError: 'TimedeltaProperties' object has no attribute 'minute'
2023-05-20 06:01:56,540 - ERROR - Uncaught exception in ZMQStream callback
Traceback (most recent call last):
  File "C:\Users\alejo\AppData\Local\Packages\PythonSoftwareFoundation.Python.3.10_qbz5n2kfra8p0\LocalCache\local-packages\Python310\site-packages\zmq\eventloop\zmqstream.py", line 584, in _run_callback
    f = callback(*args, **kwargs)
  File "C:\Users\alejo\AppData\Local\Packages\PythonSoftwareFoundation.Python.3.10_qbz5n2kfra8p0\LocalCache\local-packages\Python310\site-packages\ipykernel\iostream.py", line 120, in _handle_event
    event_f()
  File "C:\Users\alejo\AppData\Local\Packages\PythonSoftwareFoundation.Python.3.10_qbz5n2kfra8p0\LocalCache\local-packages\Python310\site-packages\ipykernel\iostream.py", line 527, in _flush
    self.session.send(
  File "C:\Users\alejo\AppData\Local\Packages\PythonSoftwareFoundation.Python.3.10_qbz5n2kfra8p0\LocalCache\local-packages\Python310\site-packages\jupyter_client\session.py", line 850, in send
    to_send = self.serialize(msg, ident)
  File "C:\Users\alejo\AppData\Local\Packages\PythonSoftwareFoundation.Python.3.10_qbz5n2kfra8p0\LocalCache\local-packages\Python310\site-packages\jupyter_client\session.py", line 719, in serialize
    content = self.pack(content)
  File "C:\Users\alejo\AppData\Local\Packages\PythonSoftwareFoundation.Python.3.10_qbz5n2kfra8p0\LocalCache\local-packages\Python310\site-packages\jupyter_client\session.py", line 95, in json_packer
    return json.dumps(
  File "C:\Program Files\WindowsApps\PythonSoftwareFoundation.Python.3.10_3.10.3056.0_x64__qbz5n2kfra8p0\lib\json\__init__.py", line 238, in dumps
    **kw).encode(obj)
  File "C:\Program Files\WindowsApps\PythonSoftwareFoundation.Python.3.10_3.10.3056.0_x64__qbz5n2kfra8p0\lib\json\encoder.py", line 199, in encode
    chunks = self.iterencode(o, _one_shot=True)
  File "C:\Program Files\WindowsApps\PythonSoftwareFoundation.Python.3.10_3.10.3056.0_x64__qbz5n2kfra8p0\lib\json\encoder.py", line 257, in iterencode
    return _iterencode(o, 0)
MemoryError
2023-05-20 06:01:56,540 - ERROR - Uncaught exception in ZMQStream callback
Traceback (most recent call last):
  File "C:\Users\alejo\AppData\Local\Packages\PythonSoftwareFoundation.Python.3.10_qbz5n2kfra8p0\LocalCache\local-packages\Python310\site-packages\zmq\eventloop\zmqstream.py", line 584, in _run_callback
    f = callback(*args, **kwargs)
  File "C:\Users\alejo\AppData\Local\Packages\PythonSoftwareFoundation.Python.3.10_qbz5n2kfra8p0\LocalCache\local-packages\Python310\site-packages\ipykernel\iostream.py", line 120, in _handle_event
    event_f()
  File "C:\Users\alejo\AppData\Local\Packages\PythonSoftwareFoundation.Python.3.10_qbz5n2kfra8p0\LocalCache\local-packages\Python310\site-packages\ipykernel\iostream.py", line 527, in _flush
    self.session.send(
  File "C:\Users\alejo\AppData\Local\Packages\PythonSoftwareFoundation.Python.3.10_qbz5n2kfra8p0\LocalCache\local-packages\Python310\site-packages\jupyter_client\session.py", line 850, in send
    to_send = self.serialize(msg, ident)
  File "C:\Users\alejo\AppData\Local\Packages\PythonSoftwareFoundation.Python.3.10_qbz5n2kfra8p0\LocalCache\local-packages\Python310\site-packages\jupyter_client\session.py", line 719, in serialize
    content = self.pack(content)
  File "C:\Users\alejo\AppData\Local\Packages\PythonSoftwareFoundation.Python.3.10_qbz5n2kfra8p0\LocalCache\local-packages\Python310\site-packages\jupyter_client\session.py", line 95, in json_packer
    return json.dumps(
  File "C:\Program Files\WindowsApps\PythonSoftwareFoundation.Python.3.10_3.10.3056.0_x64__qbz5n2kfra8p0\lib\json\__init__.py", line 238, in dumps
    **kw).encode(obj)
  File "C:\Program Files\WindowsApps\PythonSoftwareFoundation.Python.3.10_3.10.3056.0_x64__qbz5n2kfra8p0\lib\json\encoder.py", line 199, in encode
    chunks = self.iterencode(o, _one_shot=True)
  File "C:\Program Files\WindowsApps\PythonSoftwareFoundation.Python.3.10_3.10.3056.0_x64__qbz5n2kfra8p0\lib\json\encoder.py", line 257, in iterencode
    return _iterencode(o, 0)
MemoryError
2023-05-20 06:01:56,540 - ERROR - Uncaught exception in ZMQStream callback
Traceback (most recent call last):
  File "C:\Users\alejo\AppData\Local\Packages\PythonSoftwareFoundation.Python.3.10_qbz5n2kfra8p0\LocalCache\local-packages\Python310\site-packages\zmq\eventloop\zmqstream.py", line 584, in _run_callback
    f = callback(*args, **kwargs)
  File "C:\Users\alejo\AppData\Local\Packages\PythonSoftwareFoundation.Python.3.10_qbz5n2kfra8p0\LocalCache\local-packages\Python310\site-packages\ipykernel\iostream.py", line 120, in _handle_event
    event_f()
  File "C:\Users\alejo\AppData\Local\Packages\PythonSoftwareFoundation.Python.3.10_qbz5n2kfra8p0\LocalCache\local-packages\Python310\site-packages\ipykernel\iostream.py", line 527, in _flush
    self.session.send(
  File "C:\Users\alejo\AppData\Local\Packages\PythonSoftwareFoundation.Python.3.10_qbz5n2kfra8p0\LocalCache\local-packages\Python310\site-packages\jupyter_client\session.py", line 850, in send
    to_send = self.serialize(msg, ident)
  File "C:\Users\alejo\AppData\Local\Packages\PythonSoftwareFoundation.Python.3.10_qbz5n2kfra8p0\LocalCache\local-packages\Python310\site-packages\jupyter_client\session.py", line 719, in serialize
    content = self.pack(content)
  File "C:\Users\alejo\AppData\Local\Packages\PythonSoftwareFoundation.Python.3.10_qbz5n2kfra8p0\LocalCache\local-packages\Python310\site-packages\jupyter_client\session.py", line 95, in json_packer
    return json.dumps(
  File "C:\Program Files\WindowsApps\PythonSoftwareFoundation.Python.3.10_3.10.3056.0_x64__qbz5n2kfra8p0\lib\json\__init__.py", line 238, in dumps
    **kw).encode(obj)
  File "C:\Program Files\WindowsApps\PythonSoftwareFoundation.Python.3.10_3.10.3056.0_x64__qbz5n2kfra8p0\lib\json\encoder.py", line 199, in encode
    chunks = self.iterencode(o, _one_shot=True)
  File "C:\Program Files\WindowsApps\PythonSoftwareFoundation.Python.3.10_3.10.3056.0_x64__qbz5n2kfra8p0\lib\json\encoder.py", line 257, in iterencode
    return _iterencode(o, 0)
MemoryError
2023-05-20 06:01:56,540 - ERROR - Uncaught exception in ZMQStream callback
Traceback (most recent call last):
  File "C:\Users\alejo\AppData\Local\Packages\PythonSoftwareFoundation.Python.3.10_qbz5n2kfra8p0\LocalCache\local-packages\Python310\site-packages\zmq\eventloop\zmqstream.py", line 584, in _run_callback
    f = callback(*args, **kwargs)
  File "C:\Users\alejo\AppData\Local\Packages\PythonSoftwareFoundation.Python.3.10_qbz5n2kfra8p0\LocalCache\local-packages\Python310\site-packages\ipykernel\iostream.py", line 120, in _handle_event
    event_f()
  File "C:\Users\alejo\AppData\Local\Packages\PythonSoftwareFoundation.Python.3.10_qbz5n2kfra8p0\LocalCache\local-packages\Python310\site-packages\ipykernel\iostream.py", line 527, in _flush
    self.session.send(
  File "C:\Users\alejo\AppData\Local\Packages\PythonSoftwareFoundation.Python.3.10_qbz5n2kfra8p0\LocalCache\local-packages\Python310\site-packages\jupyter_client\session.py", line 850, in send
    to_send = self.serialize(msg, ident)
  File "C:\Users\alejo\AppData\Local\Packages\PythonSoftwareFoundation.Python.3.10_qbz5n2kfra8p0\LocalCache\local-packages\Python310\site-packages\jupyter_client\session.py", line 719, in serialize
    content = self.pack(content)
  File "C:\Users\alejo\AppData\Local\Packages\PythonSoftwareFoundation.Python.3.10_qbz5n2kfra8p0\LocalCache\local-packages\Python310\site-packages\jupyter_client\session.py", line 95, in json_packer
    return json.dumps(
  File "C:\Program Files\WindowsApps\PythonSoftwareFoundation.Python.3.10_3.10.3056.0_x64__qbz5n2kfra8p0\lib\json\__init__.py", line 238, in dumps
    **kw).encode(obj)
  File "C:\Program Files\WindowsApps\PythonSoftwareFoundation.Python.3.10_3.10.3056.0_x64__qbz5n2kfra8p0\lib\json\encoder.py", line 199, in encode
    chunks = self.iterencode(o, _one_shot=True)
  File "C:\Program Files\WindowsApps\PythonSoftwareFoundation.Python.3.10_3.10.3056.0_x64__qbz5n2kfra8p0\lib\json\encoder.py", line 257, in iterencode
    return _iterencode(o, 0)
MemoryError
2023-05-20 06:01:56,540 - ERROR - Uncaught exception in ZMQStream callback
Traceback (most recent call last):
  File "C:\Users\alejo\AppData\Local\Packages\PythonSoftwareFoundation.Python.3.10_qbz5n2kfra8p0\LocalCache\local-packages\Python310\site-packages\zmq\eventloop\zmqstream.py", line 584, in _run_callback
    f = callback(*args, **kwargs)
  File "C:\Users\alejo\AppData\Local\Packages\PythonSoftwareFoundation.Python.3.10_qbz5n2kfra8p0\LocalCache\local-packages\Python310\site-packages\ipykernel\iostream.py", line 120, in _handle_event
    event_f()
  File "C:\Users\alejo\AppData\Local\Packages\PythonSoftwareFoundation.Python.3.10_qbz5n2kfra8p0\LocalCache\local-packages\Python310\site-packages\ipykernel\iostream.py", line 527, in _flush
    self.session.send(
  File "C:\Users\alejo\AppData\Local\Packages\PythonSoftwareFoundation.Python.3.10_qbz5n2kfra8p0\LocalCache\local-packages\Python310\site-packages\jupyter_client\session.py", line 850, in send
    to_send = self.serialize(msg, ident)
  File "C:\Users\alejo\AppData\Local\Packages\PythonSoftwareFoundation.Python.3.10_qbz5n2kfra8p0\LocalCache\local-packages\Python310\site-packages\jupyter_client\session.py", line 719, in serialize
    content = self.pack(content)
  File "C:\Users\alejo\AppData\Local\Packages\PythonSoftwareFoundation.Python.3.10_qbz5n2kfra8p0\LocalCache\local-packages\Python310\site-packages\jupyter_client\session.py", line 95, in json_packer
    return json.dumps(
  File "C:\Program Files\WindowsApps\PythonSoftwareFoundation.Python.3.10_3.10.3056.0_x64__qbz5n2kfra8p0\lib\json\__init__.py", line 238, in dumps
    **kw).encode(obj)
  File "C:\Program Files\WindowsApps\PythonSoftwareFoundation.Python.3.10_3.10.3056.0_x64__qbz5n2kfra8p0\lib\json\encoder.py", line 199, in encode
    chunks = self.iterencode(o, _one_shot=True)
  File "C:\Program Files\WindowsApps\PythonSoftwareFoundation.Python.3.10_3.10.3056.0_x64__qbz5n2kfra8p0\lib\json\encoder.py", line 257, in iterencode
    return _iterencode(o, 0)
MemoryError
2023-05-20 06:01:56,634 - ERROR - Uncaught exception in zmqstream callback
Traceback (most recent call last):
  File "C:\Users\alejo\AppData\Local\Packages\PythonSoftwareFoundation.Python.3.10_qbz5n2kfra8p0\LocalCache\local-packages\Python310\site-packages\zmq\eventloop\zmqstream.py", line 621, in _handle_events
    self._handle_recv()
  File "C:\Users\alejo\AppData\Local\Packages\PythonSoftwareFoundation.Python.3.10_qbz5n2kfra8p0\LocalCache\local-packages\Python310\site-packages\zmq\eventloop\zmqstream.py", line 650, in _handle_recv
    self._run_callback(callback, msg)
  File "C:\Users\alejo\AppData\Local\Packages\PythonSoftwareFoundation.Python.3.10_qbz5n2kfra8p0\LocalCache\local-packages\Python310\site-packages\zmq\eventloop\zmqstream.py", line 584, in _run_callback
    f = callback(*args, **kwargs)
  File "C:\Users\alejo\AppData\Local\Packages\PythonSoftwareFoundation.Python.3.10_qbz5n2kfra8p0\LocalCache\local-packages\Python310\site-packages\ipykernel\iostream.py", line 120, in _handle_event
    event_f()
  File "C:\Users\alejo\AppData\Local\Packages\PythonSoftwareFoundation.Python.3.10_qbz5n2kfra8p0\LocalCache\local-packages\Python310\site-packages\ipykernel\iostream.py", line 527, in _flush
    self.session.send(
  File "C:\Users\alejo\AppData\Local\Packages\PythonSoftwareFoundation.Python.3.10_qbz5n2kfra8p0\LocalCache\local-packages\Python310\site-packages\jupyter_client\session.py", line 850, in send
    to_send = self.serialize(msg, ident)
  File "C:\Users\alejo\AppData\Local\Packages\PythonSoftwareFoundation.Python.3.10_qbz5n2kfra8p0\LocalCache\local-packages\Python310\site-packages\jupyter_client\session.py", line 719, in serialize
    content = self.pack(content)
  File "C:\Users\alejo\AppData\Local\Packages\PythonSoftwareFoundation.Python.3.10_qbz5n2kfra8p0\LocalCache\local-packages\Python310\site-packages\jupyter_client\session.py", line 95, in json_packer
    return json.dumps(
  File "C:\Program Files\WindowsApps\PythonSoftwareFoundation.Python.3.10_3.10.3056.0_x64__qbz5n2kfra8p0\lib\json\__init__.py", line 238, in dumps
    **kw).encode(obj)
  File "C:\Program Files\WindowsApps\PythonSoftwareFoundation.Python.3.10_3.10.3056.0_x64__qbz5n2kfra8p0\lib\json\encoder.py", line 199, in encode
    chunks = self.iterencode(o, _one_shot=True)
  File "C:\Program Files\WindowsApps\PythonSoftwareFoundation.Python.3.10_3.10.3056.0_x64__qbz5n2kfra8p0\lib\json\encoder.py", line 257, in iterencode
    return _iterencode(o, 0)
MemoryError
2023-05-20 06:01:56,634 - ERROR - Uncaught exception in zmqstream callback
Traceback (most recent call last):
  File "C:\Users\alejo\AppData\Local\Packages\PythonSoftwareFoundation.Python.3.10_qbz5n2kfra8p0\LocalCache\local-packages\Python310\site-packages\zmq\eventloop\zmqstream.py", line 621, in _handle_events
    self._handle_recv()
  File "C:\Users\alejo\AppData\Local\Packages\PythonSoftwareFoundation.Python.3.10_qbz5n2kfra8p0\LocalCache\local-packages\Python310\site-packages\zmq\eventloop\zmqstream.py", line 650, in _handle_recv
    self._run_callback(callback, msg)
  File "C:\Users\alejo\AppData\Local\Packages\PythonSoftwareFoundation.Python.3.10_qbz5n2kfra8p0\LocalCache\local-packages\Python310\site-packages\zmq\eventloop\zmqstream.py", line 584, in _run_callback
    f = callback(*args, **kwargs)
  File "C:\Users\alejo\AppData\Local\Packages\PythonSoftwareFoundation.Python.3.10_qbz5n2kfra8p0\LocalCache\local-packages\Python310\site-packages\ipykernel\iostream.py", line 120, in _handle_event
    event_f()
  File "C:\Users\alejo\AppData\Local\Packages\PythonSoftwareFoundation.Python.3.10_qbz5n2kfra8p0\LocalCache\local-packages\Python310\site-packages\ipykernel\iostream.py", line 527, in _flush
    self.session.send(
  File "C:\Users\alejo\AppData\Local\Packages\PythonSoftwareFoundation.Python.3.10_qbz5n2kfra8p0\LocalCache\local-packages\Python310\site-packages\jupyter_client\session.py", line 850, in send
    to_send = self.serialize(msg, ident)
  File "C:\Users\alejo\AppData\Local\Packages\PythonSoftwareFoundation.Python.3.10_qbz5n2kfra8p0\LocalCache\local-packages\Python310\site-packages\jupyter_client\session.py", line 719, in serialize
    content = self.pack(content)
  File "C:\Users\alejo\AppData\Local\Packages\PythonSoftwareFoundation.Python.3.10_qbz5n2kfra8p0\LocalCache\local-packages\Python310\site-packages\jupyter_client\session.py", line 95, in json_packer
    return json.dumps(
  File "C:\Program Files\WindowsApps\PythonSoftwareFoundation.Python.3.10_3.10.3056.0_x64__qbz5n2kfra8p0\lib\json\__init__.py", line 238, in dumps
    **kw).encode(obj)
  File "C:\Program Files\WindowsApps\PythonSoftwareFoundation.Python.3.10_3.10.3056.0_x64__qbz5n2kfra8p0\lib\json\encoder.py", line 199, in encode
    chunks = self.iterencode(o, _one_shot=True)
  File "C:\Program Files\WindowsApps\PythonSoftwareFoundation.Python.3.10_3.10.3056.0_x64__qbz5n2kfra8p0\lib\json\encoder.py", line 257, in iterencode
    return _iterencode(o, 0)
MemoryError
2023-05-20 06:01:56,634 - ERROR - Uncaught exception in zmqstream callback
Traceback (most recent call last):
  File "C:\Users\alejo\AppData\Local\Packages\PythonSoftwareFoundation.Python.3.10_qbz5n2kfra8p0\LocalCache\local-packages\Python310\site-packages\zmq\eventloop\zmqstream.py", line 621, in _handle_events
    self._handle_recv()
  File "C:\Users\alejo\AppData\Local\Packages\PythonSoftwareFoundation.Python.3.10_qbz5n2kfra8p0\LocalCache\local-packages\Python310\site-packages\zmq\eventloop\zmqstream.py", line 650, in _handle_recv
    self._run_callback(callback, msg)
  File "C:\Users\alejo\AppData\Local\Packages\PythonSoftwareFoundation.Python.3.10_qbz5n2kfra8p0\LocalCache\local-packages\Python310\site-packages\zmq\eventloop\zmqstream.py", line 584, in _run_callback
    f = callback(*args, **kwargs)
  File "C:\Users\alejo\AppData\Local\Packages\PythonSoftwareFoundation.Python.3.10_qbz5n2kfra8p0\LocalCache\local-packages\Python310\site-packages\ipykernel\iostream.py", line 120, in _handle_event
    event_f()
  File "C:\Users\alejo\AppData\Local\Packages\PythonSoftwareFoundation.Python.3.10_qbz5n2kfra8p0\LocalCache\local-packages\Python310\site-packages\ipykernel\iostream.py", line 527, in _flush
    self.session.send(
  File "C:\Users\alejo\AppData\Local\Packages\PythonSoftwareFoundation.Python.3.10_qbz5n2kfra8p0\LocalCache\local-packages\Python310\site-packages\jupyter_client\session.py", line 850, in send
    to_send = self.serialize(msg, ident)
  File "C:\Users\alejo\AppData\Local\Packages\PythonSoftwareFoundation.Python.3.10_qbz5n2kfra8p0\LocalCache\local-packages\Python310\site-packages\jupyter_client\session.py", line 719, in serialize
    content = self.pack(content)
  File "C:\Users\alejo\AppData\Local\Packages\PythonSoftwareFoundation.Python.3.10_qbz5n2kfra8p0\LocalCache\local-packages\Python310\site-packages\jupyter_client\session.py", line 95, in json_packer
    return json.dumps(
  File "C:\Program Files\WindowsApps\PythonSoftwareFoundation.Python.3.10_3.10.3056.0_x64__qbz5n2kfra8p0\lib\json\__init__.py", line 238, in dumps
    **kw).encode(obj)
  File "C:\Program Files\WindowsApps\PythonSoftwareFoundation.Python.3.10_3.10.3056.0_x64__qbz5n2kfra8p0\lib\json\encoder.py", line 199, in encode
    chunks = self.iterencode(o, _one_shot=True)
  File "C:\Program Files\WindowsApps\PythonSoftwareFoundation.Python.3.10_3.10.3056.0_x64__qbz5n2kfra8p0\lib\json\encoder.py", line 257, in iterencode
    return _iterencode(o, 0)
MemoryError
2023-05-20 06:01:56,634 - ERROR - Uncaught exception in zmqstream callback
Traceback (most recent call last):
  File "C:\Users\alejo\AppData\Local\Packages\PythonSoftwareFoundation.Python.3.10_qbz5n2kfra8p0\LocalCache\local-packages\Python310\site-packages\zmq\eventloop\zmqstream.py", line 621, in _handle_events
    self._handle_recv()
  File "C:\Users\alejo\AppData\Local\Packages\PythonSoftwareFoundation.Python.3.10_qbz5n2kfra8p0\LocalCache\local-packages\Python310\site-packages\zmq\eventloop\zmqstream.py", line 650, in _handle_recv
    self._run_callback(callback, msg)
  File "C:\Users\alejo\AppData\Local\Packages\PythonSoftwareFoundation.Python.3.10_qbz5n2kfra8p0\LocalCache\local-packages\Python310\site-packages\zmq\eventloop\zmqstream.py", line 584, in _run_callback
    f = callback(*args, **kwargs)
  File "C:\Users\alejo\AppData\Local\Packages\PythonSoftwareFoundation.Python.3.10_qbz5n2kfra8p0\LocalCache\local-packages\Python310\site-packages\ipykernel\iostream.py", line 120, in _handle_event
    event_f()
  File "C:\Users\alejo\AppData\Local\Packages\PythonSoftwareFoundation.Python.3.10_qbz5n2kfra8p0\LocalCache\local-packages\Python310\site-packages\ipykernel\iostream.py", line 527, in _flush
    self.session.send(
  File "C:\Users\alejo\AppData\Local\Packages\PythonSoftwareFoundation.Python.3.10_qbz5n2kfra8p0\LocalCache\local-packages\Python310\site-packages\jupyter_client\session.py", line 850, in send
    to_send = self.serialize(msg, ident)
  File "C:\Users\alejo\AppData\Local\Packages\PythonSoftwareFoundation.Python.3.10_qbz5n2kfra8p0\LocalCache\local-packages\Python310\site-packages\jupyter_client\session.py", line 719, in serialize
    content = self.pack(content)
  File "C:\Users\alejo\AppData\Local\Packages\PythonSoftwareFoundation.Python.3.10_qbz5n2kfra8p0\LocalCache\local-packages\Python310\site-packages\jupyter_client\session.py", line 95, in json_packer
    return json.dumps(
  File "C:\Program Files\WindowsApps\PythonSoftwareFoundation.Python.3.10_3.10.3056.0_x64__qbz5n2kfra8p0\lib\json\__init__.py", line 238, in dumps
    **kw).encode(obj)
  File "C:\Program Files\WindowsApps\PythonSoftwareFoundation.Python.3.10_3.10.3056.0_x64__qbz5n2kfra8p0\lib\json\encoder.py", line 199, in encode
    chunks = self.iterencode(o, _one_shot=True)
  File "C:\Program Files\WindowsApps\PythonSoftwareFoundation.Python.3.10_3.10.3056.0_x64__qbz5n2kfra8p0\lib\json\encoder.py", line 257, in iterencode
    return _iterencode(o, 0)
MemoryError
2023-05-20 06:01:56,634 - ERROR - Uncaught exception in zmqstream callback
Traceback (most recent call last):
  File "C:\Users\alejo\AppData\Local\Packages\PythonSoftwareFoundation.Python.3.10_qbz5n2kfra8p0\LocalCache\local-packages\Python310\site-packages\zmq\eventloop\zmqstream.py", line 621, in _handle_events
    self._handle_recv()
  File "C:\Users\alejo\AppData\Local\Packages\PythonSoftwareFoundation.Python.3.10_qbz5n2kfra8p0\LocalCache\local-packages\Python310\site-packages\zmq\eventloop\zmqstream.py", line 650, in _handle_recv
    self._run_callback(callback, msg)
  File "C:\Users\alejo\AppData\Local\Packages\PythonSoftwareFoundation.Python.3.10_qbz5n2kfra8p0\LocalCache\local-packages\Python310\site-packages\zmq\eventloop\zmqstream.py", line 584, in _run_callback
    f = callback(*args, **kwargs)
  File "C:\Users\alejo\AppData\Local\Packages\PythonSoftwareFoundation.Python.3.10_qbz5n2kfra8p0\LocalCache\local-packages\Python310\site-packages\ipykernel\iostream.py", line 120, in _handle_event
    event_f()
  File "C:\Users\alejo\AppData\Local\Packages\PythonSoftwareFoundation.Python.3.10_qbz5n2kfra8p0\LocalCache\local-packages\Python310\site-packages\ipykernel\iostream.py", line 527, in _flush
    self.session.send(
  File "C:\Users\alejo\AppData\Local\Packages\PythonSoftwareFoundation.Python.3.10_qbz5n2kfra8p0\LocalCache\local-packages\Python310\site-packages\jupyter_client\session.py", line 850, in send
    to_send = self.serialize(msg, ident)
  File "C:\Users\alejo\AppData\Local\Packages\PythonSoftwareFoundation.Python.3.10_qbz5n2kfra8p0\LocalCache\local-packages\Python310\site-packages\jupyter_client\session.py", line 719, in serialize
    content = self.pack(content)
  File "C:\Users\alejo\AppData\Local\Packages\PythonSoftwareFoundation.Python.3.10_qbz5n2kfra8p0\LocalCache\local-packages\Python310\site-packages\jupyter_client\session.py", line 95, in json_packer
    return json.dumps(
  File "C:\Program Files\WindowsApps\PythonSoftwareFoundation.Python.3.10_3.10.3056.0_x64__qbz5n2kfra8p0\lib\json\__init__.py", line 238, in dumps
    **kw).encode(obj)
  File "C:\Program Files\WindowsApps\PythonSoftwareFoundation.Python.3.10_3.10.3056.0_x64__qbz5n2kfra8p0\lib\json\encoder.py", line 199, in encode
    chunks = self.iterencode(o, _one_shot=True)
  File "C:\Program Files\WindowsApps\PythonSoftwareFoundation.Python.3.10_3.10.3056.0_x64__qbz5n2kfra8p0\lib\json\encoder.py", line 257, in iterencode
    return _iterencode(o, 0)
MemoryError
2023-05-20 06:01:56,639 - ERROR - Exception in callback BaseAsyncIOLoop._handle_events(1660, 1)
handle: <Handle BaseAsyncIOLoop._handle_events(1660, 1)>
Traceback (most recent call last):
  File "C:\Program Files\WindowsApps\PythonSoftwareFoundation.Python.3.10_3.10.3056.0_x64__qbz5n2kfra8p0\lib\asyncio\events.py", line 80, in _run
    self._context.run(self._callback, *self._args)
  File "C:\Users\alejo\AppData\Local\Packages\PythonSoftwareFoundation.Python.3.10_qbz5n2kfra8p0\LocalCache\local-packages\Python310\site-packages\tornado\platform\asyncio.py", line 206, in _handle_events
    handler_func(fileobj, events)
  File "C:\Users\alejo\AppData\Local\Packages\PythonSoftwareFoundation.Python.3.10_qbz5n2kfra8p0\LocalCache\local-packages\Python310\site-packages\zmq\eventloop\zmqstream.py", line 621, in _handle_events
    self._handle_recv()
  File "C:\Users\alejo\AppData\Local\Packages\PythonSoftwareFoundation.Python.3.10_qbz5n2kfra8p0\LocalCache\local-packages\Python310\site-packages\zmq\eventloop\zmqstream.py", line 650, in _handle_recv
    self._run_callback(callback, msg)
  File "C:\Users\alejo\AppData\Local\Packages\PythonSoftwareFoundation.Python.3.10_qbz5n2kfra8p0\LocalCache\local-packages\Python310\site-packages\zmq\eventloop\zmqstream.py", line 584, in _run_callback
    f = callback(*args, **kwargs)
  File "C:\Users\alejo\AppData\Local\Packages\PythonSoftwareFoundation.Python.3.10_qbz5n2kfra8p0\LocalCache\local-packages\Python310\site-packages\ipykernel\iostream.py", line 120, in _handle_event
    event_f()
  File "C:\Users\alejo\AppData\Local\Packages\PythonSoftwareFoundation.Python.3.10_qbz5n2kfra8p0\LocalCache\local-packages\Python310\site-packages\ipykernel\iostream.py", line 527, in _flush
    self.session.send(
  File "C:\Users\alejo\AppData\Local\Packages\PythonSoftwareFoundation.Python.3.10_qbz5n2kfra8p0\LocalCache\local-packages\Python310\site-packages\jupyter_client\session.py", line 850, in send
    to_send = self.serialize(msg, ident)
  File "C:\Users\alejo\AppData\Local\Packages\PythonSoftwareFoundation.Python.3.10_qbz5n2kfra8p0\LocalCache\local-packages\Python310\site-packages\jupyter_client\session.py", line 719, in serialize
    content = self.pack(content)
  File "C:\Users\alejo\AppData\Local\Packages\PythonSoftwareFoundation.Python.3.10_qbz5n2kfra8p0\LocalCache\local-packages\Python310\site-packages\jupyter_client\session.py", line 95, in json_packer
    return json.dumps(
  File "C:\Program Files\WindowsApps\PythonSoftwareFoundation.Python.3.10_3.10.3056.0_x64__qbz5n2kfra8p0\lib\json\__init__.py", line 238, in dumps
    **kw).encode(obj)
  File "C:\Program Files\WindowsApps\PythonSoftwareFoundation.Python.3.10_3.10.3056.0_x64__qbz5n2kfra8p0\lib\json\encoder.py", line 199, in encode
    chunks = self.iterencode(o, _one_shot=True)
  File "C:\Program Files\WindowsApps\PythonSoftwareFoundation.Python.3.10_3.10.3056.0_x64__qbz5n2kfra8p0\lib\json\encoder.py", line 257, in iterencode
    return _iterencode(o, 0)
MemoryError
2023-05-20 06:01:56,639 - ERROR - Exception in callback BaseAsyncIOLoop._handle_events(1660, 1)
handle: <Handle BaseAsyncIOLoop._handle_events(1660, 1)>
Traceback (most recent call last):
  File "C:\Program Files\WindowsApps\PythonSoftwareFoundation.Python.3.10_3.10.3056.0_x64__qbz5n2kfra8p0\lib\asyncio\events.py", line 80, in _run
    self._context.run(self._callback, *self._args)
  File "C:\Users\alejo\AppData\Local\Packages\PythonSoftwareFoundation.Python.3.10_qbz5n2kfra8p0\LocalCache\local-packages\Python310\site-packages\tornado\platform\asyncio.py", line 206, in _handle_events
    handler_func(fileobj, events)
  File "C:\Users\alejo\AppData\Local\Packages\PythonSoftwareFoundation.Python.3.10_qbz5n2kfra8p0\LocalCache\local-packages\Python310\site-packages\zmq\eventloop\zmqstream.py", line 621, in _handle_events
    self._handle_recv()
  File "C:\Users\alejo\AppData\Local\Packages\PythonSoftwareFoundation.Python.3.10_qbz5n2kfra8p0\LocalCache\local-packages\Python310\site-packages\zmq\eventloop\zmqstream.py", line 650, in _handle_recv
    self._run_callback(callback, msg)
  File "C:\Users\alejo\AppData\Local\Packages\PythonSoftwareFoundation.Python.3.10_qbz5n2kfra8p0\LocalCache\local-packages\Python310\site-packages\zmq\eventloop\zmqstream.py", line 584, in _run_callback
    f = callback(*args, **kwargs)
  File "C:\Users\alejo\AppData\Local\Packages\PythonSoftwareFoundation.Python.3.10_qbz5n2kfra8p0\LocalCache\local-packages\Python310\site-packages\ipykernel\iostream.py", line 120, in _handle_event
    event_f()
  File "C:\Users\alejo\AppData\Local\Packages\PythonSoftwareFoundation.Python.3.10_qbz5n2kfra8p0\LocalCache\local-packages\Python310\site-packages\ipykernel\iostream.py", line 527, in _flush
    self.session.send(
  File "C:\Users\alejo\AppData\Local\Packages\PythonSoftwareFoundation.Python.3.10_qbz5n2kfra8p0\LocalCache\local-packages\Python310\site-packages\jupyter_client\session.py", line 850, in send
    to_send = self.serialize(msg, ident)
  File "C:\Users\alejo\AppData\Local\Packages\PythonSoftwareFoundation.Python.3.10_qbz5n2kfra8p0\LocalCache\local-packages\Python310\site-packages\jupyter_client\session.py", line 719, in serialize
    content = self.pack(content)
  File "C:\Users\alejo\AppData\Local\Packages\PythonSoftwareFoundation.Python.3.10_qbz5n2kfra8p0\LocalCache\local-packages\Python310\site-packages\jupyter_client\session.py", line 95, in json_packer
    return json.dumps(
  File "C:\Program Files\WindowsApps\PythonSoftwareFoundation.Python.3.10_3.10.3056.0_x64__qbz5n2kfra8p0\lib\json\__init__.py", line 238, in dumps
    **kw).encode(obj)
  File "C:\Program Files\WindowsApps\PythonSoftwareFoundation.Python.3.10_3.10.3056.0_x64__qbz5n2kfra8p0\lib\json\encoder.py", line 199, in encode
    chunks = self.iterencode(o, _one_shot=True)
  File "C:\Program Files\WindowsApps\PythonSoftwareFoundation.Python.3.10_3.10.3056.0_x64__qbz5n2kfra8p0\lib\json\encoder.py", line 257, in iterencode
    return _iterencode(o, 0)
MemoryError
2023-05-20 06:01:56,639 - ERROR - Exception in callback BaseAsyncIOLoop._handle_events(1660, 1)
handle: <Handle BaseAsyncIOLoop._handle_events(1660, 1)>
Traceback (most recent call last):
  File "C:\Program Files\WindowsApps\PythonSoftwareFoundation.Python.3.10_3.10.3056.0_x64__qbz5n2kfra8p0\lib\asyncio\events.py", line 80, in _run
    self._context.run(self._callback, *self._args)
  File "C:\Users\alejo\AppData\Local\Packages\PythonSoftwareFoundation.Python.3.10_qbz5n2kfra8p0\LocalCache\local-packages\Python310\site-packages\tornado\platform\asyncio.py", line 206, in _handle_events
    handler_func(fileobj, events)
  File "C:\Users\alejo\AppData\Local\Packages\PythonSoftwareFoundation.Python.3.10_qbz5n2kfra8p0\LocalCache\local-packages\Python310\site-packages\zmq\eventloop\zmqstream.py", line 621, in _handle_events
    self._handle_recv()
  File "C:\Users\alejo\AppData\Local\Packages\PythonSoftwareFoundation.Python.3.10_qbz5n2kfra8p0\LocalCache\local-packages\Python310\site-packages\zmq\eventloop\zmqstream.py", line 650, in _handle_recv
    self._run_callback(callback, msg)
  File "C:\Users\alejo\AppData\Local\Packages\PythonSoftwareFoundation.Python.3.10_qbz5n2kfra8p0\LocalCache\local-packages\Python310\site-packages\zmq\eventloop\zmqstream.py", line 584, in _run_callback
    f = callback(*args, **kwargs)
  File "C:\Users\alejo\AppData\Local\Packages\PythonSoftwareFoundation.Python.3.10_qbz5n2kfra8p0\LocalCache\local-packages\Python310\site-packages\ipykernel\iostream.py", line 120, in _handle_event
    event_f()
  File "C:\Users\alejo\AppData\Local\Packages\PythonSoftwareFoundation.Python.3.10_qbz5n2kfra8p0\LocalCache\local-packages\Python310\site-packages\ipykernel\iostream.py", line 527, in _flush
    self.session.send(
  File "C:\Users\alejo\AppData\Local\Packages\PythonSoftwareFoundation.Python.3.10_qbz5n2kfra8p0\LocalCache\local-packages\Python310\site-packages\jupyter_client\session.py", line 850, in send
    to_send = self.serialize(msg, ident)
  File "C:\Users\alejo\AppData\Local\Packages\PythonSoftwareFoundation.Python.3.10_qbz5n2kfra8p0\LocalCache\local-packages\Python310\site-packages\jupyter_client\session.py", line 719, in serialize
    content = self.pack(content)
  File "C:\Users\alejo\AppData\Local\Packages\PythonSoftwareFoundation.Python.3.10_qbz5n2kfra8p0\LocalCache\local-packages\Python310\site-packages\jupyter_client\session.py", line 95, in json_packer
    return json.dumps(
  File "C:\Program Files\WindowsApps\PythonSoftwareFoundation.Python.3.10_3.10.3056.0_x64__qbz5n2kfra8p0\lib\json\__init__.py", line 238, in dumps
    **kw).encode(obj)
  File "C:\Program Files\WindowsApps\PythonSoftwareFoundation.Python.3.10_3.10.3056.0_x64__qbz5n2kfra8p0\lib\json\encoder.py", line 199, in encode
    chunks = self.iterencode(o, _one_shot=True)
  File "C:\Program Files\WindowsApps\PythonSoftwareFoundation.Python.3.10_3.10.3056.0_x64__qbz5n2kfra8p0\lib\json\encoder.py", line 257, in iterencode
    return _iterencode(o, 0)
MemoryError
2023-05-20 06:01:56,639 - ERROR - Exception in callback BaseAsyncIOLoop._handle_events(1660, 1)
handle: <Handle BaseAsyncIOLoop._handle_events(1660, 1)>
Traceback (most recent call last):
  File "C:\Program Files\WindowsApps\PythonSoftwareFoundation.Python.3.10_3.10.3056.0_x64__qbz5n2kfra8p0\lib\asyncio\events.py", line 80, in _run
    self._context.run(self._callback, *self._args)
  File "C:\Users\alejo\AppData\Local\Packages\PythonSoftwareFoundation.Python.3.10_qbz5n2kfra8p0\LocalCache\local-packages\Python310\site-packages\tornado\platform\asyncio.py", line 206, in _handle_events
    handler_func(fileobj, events)
  File "C:\Users\alejo\AppData\Local\Packages\PythonSoftwareFoundation.Python.3.10_qbz5n2kfra8p0\LocalCache\local-packages\Python310\site-packages\zmq\eventloop\zmqstream.py", line 621, in _handle_events
    self._handle_recv()
  File "C:\Users\alejo\AppData\Local\Packages\PythonSoftwareFoundation.Python.3.10_qbz5n2kfra8p0\LocalCache\local-packages\Python310\site-packages\zmq\eventloop\zmqstream.py", line 650, in _handle_recv
    self._run_callback(callback, msg)
  File "C:\Users\alejo\AppData\Local\Packages\PythonSoftwareFoundation.Python.3.10_qbz5n2kfra8p0\LocalCache\local-packages\Python310\site-packages\zmq\eventloop\zmqstream.py", line 584, in _run_callback
    f = callback(*args, **kwargs)
  File "C:\Users\alejo\AppData\Local\Packages\PythonSoftwareFoundation.Python.3.10_qbz5n2kfra8p0\LocalCache\local-packages\Python310\site-packages\ipykernel\iostream.py", line 120, in _handle_event
    event_f()
  File "C:\Users\alejo\AppData\Local\Packages\PythonSoftwareFoundation.Python.3.10_qbz5n2kfra8p0\LocalCache\local-packages\Python310\site-packages\ipykernel\iostream.py", line 527, in _flush
    self.session.send(
  File "C:\Users\alejo\AppData\Local\Packages\PythonSoftwareFoundation.Python.3.10_qbz5n2kfra8p0\LocalCache\local-packages\Python310\site-packages\jupyter_client\session.py", line 850, in send
    to_send = self.serialize(msg, ident)
  File "C:\Users\alejo\AppData\Local\Packages\PythonSoftwareFoundation.Python.3.10_qbz5n2kfra8p0\LocalCache\local-packages\Python310\site-packages\jupyter_client\session.py", line 719, in serialize
    content = self.pack(content)
  File "C:\Users\alejo\AppData\Local\Packages\PythonSoftwareFoundation.Python.3.10_qbz5n2kfra8p0\LocalCache\local-packages\Python310\site-packages\jupyter_client\session.py", line 95, in json_packer
    return json.dumps(
  File "C:\Program Files\WindowsApps\PythonSoftwareFoundation.Python.3.10_3.10.3056.0_x64__qbz5n2kfra8p0\lib\json\__init__.py", line 238, in dumps
    **kw).encode(obj)
  File "C:\Program Files\WindowsApps\PythonSoftwareFoundation.Python.3.10_3.10.3056.0_x64__qbz5n2kfra8p0\lib\json\encoder.py", line 199, in encode
    chunks = self.iterencode(o, _one_shot=True)
  File "C:\Program Files\WindowsApps\PythonSoftwareFoundation.Python.3.10_3.10.3056.0_x64__qbz5n2kfra8p0\lib\json\encoder.py", line 257, in iterencode
    return _iterencode(o, 0)
MemoryError
2023-05-20 06:01:56,639 - ERROR - Exception in callback BaseAsyncIOLoop._handle_events(1660, 1)
handle: <Handle BaseAsyncIOLoop._handle_events(1660, 1)>
Traceback (most recent call last):
  File "C:\Program Files\WindowsApps\PythonSoftwareFoundation.Python.3.10_3.10.3056.0_x64__qbz5n2kfra8p0\lib\asyncio\events.py", line 80, in _run
    self._context.run(self._callback, *self._args)
  File "C:\Users\alejo\AppData\Local\Packages\PythonSoftwareFoundation.Python.3.10_qbz5n2kfra8p0\LocalCache\local-packages\Python310\site-packages\tornado\platform\asyncio.py", line 206, in _handle_events
    handler_func(fileobj, events)
  File "C:\Users\alejo\AppData\Local\Packages\PythonSoftwareFoundation.Python.3.10_qbz5n2kfra8p0\LocalCache\local-packages\Python310\site-packages\zmq\eventloop\zmqstream.py", line 621, in _handle_events
    self._handle_recv()
  File "C:\Users\alejo\AppData\Local\Packages\PythonSoftwareFoundation.Python.3.10_qbz5n2kfra8p0\LocalCache\local-packages\Python310\site-packages\zmq\eventloop\zmqstream.py", line 650, in _handle_recv
    self._run_callback(callback, msg)
  File "C:\Users\alejo\AppData\Local\Packages\PythonSoftwareFoundation.Python.3.10_qbz5n2kfra8p0\LocalCache\local-packages\Python310\site-packages\zmq\eventloop\zmqstream.py", line 584, in _run_callback
    f = callback(*args, **kwargs)
  File "C:\Users\alejo\AppData\Local\Packages\PythonSoftwareFoundation.Python.3.10_qbz5n2kfra8p0\LocalCache\local-packages\Python310\site-packages\ipykernel\iostream.py", line 120, in _handle_event
    event_f()
  File "C:\Users\alejo\AppData\Local\Packages\PythonSoftwareFoundation.Python.3.10_qbz5n2kfra8p0\LocalCache\local-packages\Python310\site-packages\ipykernel\iostream.py", line 527, in _flush
    self.session.send(
  File "C:\Users\alejo\AppData\Local\Packages\PythonSoftwareFoundation.Python.3.10_qbz5n2kfra8p0\LocalCache\local-packages\Python310\site-packages\jupyter_client\session.py", line 850, in send
    to_send = self.serialize(msg, ident)
  File "C:\Users\alejo\AppData\Local\Packages\PythonSoftwareFoundation.Python.3.10_qbz5n2kfra8p0\LocalCache\local-packages\Python310\site-packages\jupyter_client\session.py", line 719, in serialize
    content = self.pack(content)
  File "C:\Users\alejo\AppData\Local\Packages\PythonSoftwareFoundation.Python.3.10_qbz5n2kfra8p0\LocalCache\local-packages\Python310\site-packages\jupyter_client\session.py", line 95, in json_packer
    return json.dumps(
  File "C:\Program Files\WindowsApps\PythonSoftwareFoundation.Python.3.10_3.10.3056.0_x64__qbz5n2kfra8p0\lib\json\__init__.py", line 238, in dumps
    **kw).encode(obj)
  File "C:\Program Files\WindowsApps\PythonSoftwareFoundation.Python.3.10_3.10.3056.0_x64__qbz5n2kfra8p0\lib\json\encoder.py", line 199, in encode
    chunks = self.iterencode(o, _one_shot=True)
  File "C:\Program Files\WindowsApps\PythonSoftwareFoundation.Python.3.10_3.10.3056.0_x64__qbz5n2kfra8p0\lib\json\encoder.py", line 257, in iterencode
    return _iterencode(o, 0)
MemoryError
2023-05-20 20:53:54,752 - ERROR - SEND Error: Host unreachable
2023-05-20 20:59:07,475 - ERROR - SEND Error: Host unreachable
2023-05-20 21:12:54,912 - ERROR - SEND Error: Host unreachable
